Workbook

Sheet Final Display
L7: THE WINNER (so far) IS
L8: =(Calculations!B5) -> Nic
L9: WITH A SCORE OF
L10: =(Calculations!B6) -> 62.83
L11: LLAMA POINTS!!!

Sheet Total Score
A1: Players: | B1: Llama | C1: Nic | D1: Taank | E1: Elephant | F1: Jorg | G1: Deadlock | H1: Veil | I1: Arch | J1: Winter | Z1: Total:
A2: Session 1: | B2: ='Session 1'!B2+'Session 1'!B7+'Session 1'!B12+'Session 1'!B17+'Session 1'!B22+'Session 1'!B27+'Session 1'!B32 -> 20 | C2: ='Session 1'!C2+'Session 1'!C7+'Session 1'!C12+'Session 1'!C17+'Session 1'!C22+'Session 1'!C27+'Session 1'!C32 -> -5 | D2: ='Session 1'!D2+'Session 1'!D7+'Session 1'!D12+'Session 1'!D17+'Session 1'!D22+'Session 1'!D27+'Session 1'!D32 -> 10 | E2: ='Session 1'!E2+'Session 1'!E7+'Session 1'!E12+'Session 1'!E17+'Session 1'!E22+'Session 1'!E27+'Session 1'!E32 -> -10 | F2: ='Session 1'!F2+'Session 1'!F7+'Session 1'!F12+'Session 1'!F17+'Session 1'!F22+'Session 1'!F27+'Session 1'!F32 -> -10 | G2: ='Session 1'!G2+'Session 1'!G7+'Session 1'!G12+'Session 1'!G17+'Session 1'!G22+'Session 1'!G27+'Session 1'!G32 -> 0 | H2: ='Session 1'!H2+'Session 1'!H7+'Session 1'!H12+'Session 1'!H17+'Session 1'!H22+'Session 1'!H27+'Session 1'!H32 -> 0 | I2: ='Session 1'!I2+'Session 1'!I7+'Session 1'!I12+'Session 1'!I17+'Session 1'!I22+'Session 1'!I27+'Session 1'!I32 -> 0 | ... Y2: ='Session 1'!Y2+'Session 1'!Y7+'Session 1'!Y12+'Session 1'!Y17+'Session 1'!Y22+'Session 1'!Y27+'Session 1'!Y32 -> 0 | Z2: =SUM(B2:Y2) -> 5
A3: Session 2: | B3: ='Session 2'!B2+'Session 2'!B7+'Session 2'!B12+'Session 2'!B17+'Session 2'!B22+'Session 2'!B27+'Session 2'!B32 -> 20 | C3: ='Session 2'!C2+'Session 2'!C7+'Session 2'!C12+'Session 2'!C17+'Session 2'!C22+'Session 2'!C27+'Session 2'!C32 -> 10 | D3: ='Session 2'!D2+'Session 2'!D7+'Session 2'!D12+'Session 2'!D17+'Session 2'!D22+'Session 2'!D27+'Session 2'!D32 -> -5 | E3: ='Session 2'!E2+'Session 2'!E7+'Session 2'!E12+'Session 2'!E17+'Session 2'!E22+'Session 2'!E27+'Session 2'!E32 -> 0 | F3: ='Session 2'!F2+'Session 2'!F7+'Session 2'!F12+'Session 2'!F17+'Session 2'!F22+'Session 2'!F27+'Session 2'!F32 -> 0 | G3: ='Session 2'!G2+'Session 2'!G7+'Session 2'!G12+'Session 2'!G17+'Session 2'!G22+'Session 2'!G27+'Session 2'!G32 -> -10 | H3: ='Session 2'!H2+'Session 2'!H7+'Session 2'!H12+'Session 2'!H17+'Session 2'!H22+'Session 2'!H27+'Session 2'!H32 -> 0 | I3: ='Session 2'!I2+'Session 2'!I7+'Session 2'!I12+'Session 2'!I17+'Session 2'!I22+'Session 2'!I27+'Session 2'!I32 -> 0 | ... Y3: ='Session 2'!Y2+'Session 2'!Y7+'Session 2'!Y12+'Session 2'!Y17+'Session 2'!Y22+'Session 2'!Y27+'Session 2'!Y32 -> 0 | Z3: =SUM(B3:Y3) -> 15
A4: Session 3: | B4: ='Session 3'!B2+'Session 3'!B7+'Session 3'!B12+'Session 3'!B17+'Session 3'!B22+'Session 3'!B27+'Session 3'!B32 -> 0 | C4: ='Session 3'!C2+'Session 3'!C7+'Session 3'!C12+'Session 3'!C17+'Session 3'!C22+'Session 3'!C27+'Session 3'!C32 -> 10 | D4: ='Session 3'!D2+'Session 3'!D7+'Session 3'!D12+'Session 3'!D17+'Session 3'!D22+'Session 3'!D27+'Session 3'!D32 -> -10 | E4: ='Session 3'!E2+'Session 3'!E7+'Session 3'!E12+'Session 3'!E17+'Session 3'!E22+'Session 3'!E27+'Session 3'!E32 -> 0 | F4: ='Session 3'!F2+'Session 3'!F7+'Session 3'!F12+'Session 3'!F17+'Session 3'!F22+'Session 3'!F27+'Session 3'!F32 -> 0 | G4: ='Session 3'!G2+'Session 3'!G7+'Session 3'!G12+'Session 3'!G17+'Session 3'!G22+'Session 3'!G27+'Session 3'!G32 -> 0 | H4: ='Session 3'!H2+'Session 3'!H7+'Session 3'!H12+'Session 3'!H17+'Session 3'!H22+'Session 3'!H27+'Session 3'!H32 -> 10 | I4: ='Session 3'!I2+'Session 3'!I7+'Session 3'!I12+'Session 3'!I17+'Session 3'!I22+'Session 3'!I27+'Session 3'!I32 -> 0 | ... Y4: ='Session 3'!Y2+'Session 3'!Y7+'Session 3'!Y12+'Session 3'!Y17+'Session 3'!Y22+'Session 3'!Y27+'Session 3'!Y32 -> 0 | Z4: =SUM(B4:Y4) -> 10
A5: Session 4: | B5: ='Session 4'!B2+'Session 4'!B7+'Session 4'!B12+'Session 4'!B17+'Session 4'!B22+'Session 4'!B27+'Session 4'!B32 -> -2.5 | C5: ='Session 4'!C2+'Session 4'!C7+'Session 4'!C12+'Session 4'!C17+'Session 4'!C22+'Session 4'!C27+'Session 4'!C32 -> 30 | D5: ='Session 4'!D2+'Session 4'!D7+'Session 4'!D12+'Session 4'!D17+'Session 4'!D22+'Session 4'!D27+'Session 4'!D32 -> -7.5 | E5: ='Session 4'!E2+'Session 4'!E7+'Session 4'!E12+'Session 4'!E17+'Session 4'!E22+'Session 4'!E27+'Session 4'!E32 -> 0 | F5: ='Session 4'!F2+'Session 4'!F7+'Session 4'!F12+'Session 4'!F17+'Session 4'!F22+'Session 4'!F27+'Session 4'!F32 -> -12.5 | G5: ='Session 4'!G2+'Session 4'!G7+'Session 4'!G12+'Session 4'!G17+'Session 4'!G22+'Session 4'!G27+'Session 4'!G32 -> -12.5 | H5: ='Session 4'!H2+'Session 4'!H7+'Session 4'!H12+'Session 4'!H17+'Session 4'!H22+'Session 4'!H27+'Session 4'!H32 -> 25 | I5: ='Session 4'!I2+'Session 4'!I7+'Session 4'!I12+'Session 4'!I17+'Session 4'!I22+'Session 4'!I27+'Session 4'!I32 -> -12.5 | ... Y5: ='Session 4'!Y2+'Session 4'!Y7+'Session 4'!Y12+'Session 4'!Y17+'Session 4'!Y22+'Session 4'!Y27+'Session 4'!Y32 -> 0 | Z5: =SUM(B5:Y5) -> -5
A6: Session 5: | B6: ='Session 5'!B2+'Session 5'!B7+'Session 5'!B12+'Session 5'!B17+'Session 5'!B22+'Session 5'!B27+'Session 5'!B32 -> 0 | C6: ='Session 5'!C2+'Session 5'!C7+'Session 5'!C12+'Session 5'!C17+'Session 5'!C22+'Session 5'!C27+'Session 5'!C32 -> 0 | D6: ='Session 5'!D2+'Session 5'!D7+'Session 5'!D12+'Session 5'!D17+'Session 5'!D22+'Session 5'!D27+'Session 5'!D32 -> 0 | E6: ='Session 5'!E2+'Session 5'!E7+'Session 5'!E12+'Session 5'!E17+'Session 5'!E22+'Session 5'!E27+'Session 5'!E32 -> 0 | F6: ='Session 5'!F2+'Session 5'!F7+'Session 5'!F12+'Session 5'!F17+'Session 5'!F22+'Session 5'!F27+'Session 5'!F32 -> 0 | G6: ='Session 5'!G2+'Session 5'!G7+'Session 5'!G12+'Session 5'!G17+'Session 5'!G22+'Session 5'!G27+'Session 5'!G32 -> 0 | H6: ='Session 5'!H2+'Session 5'!H7+'Session 5'!H12+'Session 5'!H17+'Session 5'!H22+'Session 5'!H27+'Session 5'!H32 -> 0 | I6: ='Session 5'!I2+'Session 5'!I7+'Session 5'!I12+'Session 5'!I17+'Session 5'!I22+'Session 5'!I27+'Session 5'!I32 -> 0 | ... Y6: ='Session 5'!Y2+'Session 5'!Y7+'Session 5'!Y12+'Session 5'!Y17+'Session 5'!Y22+'Session 5'!Y27+'Session 5'!Y32 -> 0 | Z6: =SUM(B6:Y6) -> 0
A7: Session 6: | B7: ='Session 6'!B2+'Session 6'!B7+'Session 6'!B12+'Session 6'!B17+'Session 6'!B22+'Session 6'!B27+'Session 6'!B32 -> 0 | C7: ='Session 6'!C2+'Session 6'!C7+'Session 6'!C12+'Session 6'!C17+'Session 6'!C22+'Session 6'!C27+'Session 6'!C32 -> 0 | D7: ='Session 6'!D2+'Session 6'!D7+'Session 6'!D12+'Session 6'!D17+'Session 6'!D22+'Session 6'!D27+'Session 6'!D32 -> 0 | E7: ='Session 6'!E2+'Session 6'!E7+'Session 6'!E12+'Session 6'!E17+'Session 6'!E22+'Session 6'!E27+'Session 6'!E32 -> 0 | F7: ='Session 6'!F2+'Session 6'!F7+'Session 6'!F12+'Session 6'!F17+'Session 6'!F22+'Session 6'!F27+'Session 6'!F32 -> 0 | G7: ='Session 6'!G2+'Session 6'!G7+'Session 6'!G12+'Session 6'!G17+'Session 6'!G22+'Session 6'!G27+'Session 6'!G32 -> 0 | H7: ='Session 6'!H2+'Session 6'!H7+'Session 6'!H12+'Session 6'!H17+'Session 6'!H22+'Session 6'!H27+'Session 6'!H32 -> 0 | I7: ='Session 6'!I2+'Session 6'!I7+'Session 6'!I12+'Session 6'!I17+'Session 6'!I22+'Session 6'!I27+'Session 6'!I32 -> 0 | ... Y7: ='Session 6'!Y2+'Session 6'!Y7+'Session 6'!Y12+'Session 6'!Y17+'Session 6'!Y22+'Session 6'!Y27+'Session 6'!Y32 -> 0 | Z7: =SUM(B7:Y7) -> 0
A8: Session 7: | B8: ='Session 7'!B2+'Session 7'!B7+'Session 7'!B12+'Session 7'!B17+'Session 7'!B22+'Session 7'!B27+'Session 7'!B32 -> 0 | C8: ='Session 7'!C2+'Session 7'!C7+'Session 7'!C12+'Session 7'!C17+'Session 7'!C22+'Session 7'!C27+'Session 7'!C32 -> 0 | D8: ='Session 7'!D2+'Session 7'!D7+'Session 7'!D12+'Session 7'!D17+'Session 7'!D22+'Session 7'!D27+'Session 7'!D32 -> 0 | E8: ='Session 7'!E2+'Session 7'!E7+'Session 7'!E12+'Session 7'!E17+'Session 7'!E22+'Session 7'!E27+'Session 7'!E32 -> 0 | F8: ='Session 7'!F2+'Session 7'!F7+'Session 7'!F12+'Session 7'!F17+'Session 7'!F22+'Session 7'!F27+'Session 7'!F32 -> 0 | G8: ='Session 7'!G2+'Session 7'!G7+'Session 7'!G12+'Session 7'!G17+'Session 7'!G22+'Session 7'!G27+'Session 7'!G32 -> 0 | H8: ='Session 7'!H2+'Session 7'!H7+'Session 7'!H12+'Session 7'!H17+'Session 7'!H22+'Session 7'!H27+'Session 7'!H32 -> 0 | I8: ='Session 7'!I2+'Session 7'!I7+'Session 7'!I12+'Session 7'!I17+'Session 7'!I22+'Session 7'!I27+'Session 7'!I32 -> 0 | ... Y8: ='Session 7'!Y2+'Session 7'!Y7+'Session 7'!Y12+'Session 7'!Y17+'Session 7'!Y22+'Session 7'!Y27+'Session 7'!Y32 -> 0 | Z8: =SUM(B8:Y8) -> 0
A9: Session 8: | B9: ='Session 8'!B2+'Session 8'!B7+'Session 8'!B12+'Session 8'!B17+'Session 8'!B22+'Session 8'!B27+'Session 8'!B32 -> 0 | C9: ='Session 8'!C2+'Session 8'!C7+'Session 8'!C12+'Session 8'!C17+'Session 8'!C22+'Session 8'!C27+'Session 8'!C32 -> 0 | D9: ='Session 8'!D2+'Session 8'!D7+'Session 8'!D12+'Session 8'!D17+'Session 8'!D22+'Session 8'!D27+'Session 8'!D32 -> 0 | E9: ='Session 8'!E2+'Session 8'!E7+'Session 8'!E12+'Session 8'!E17+'Session 8'!E22+'Session 8'!E27+'Session 8'!E32 -> 0 | F9: ='Session 8'!F2+'Session 8'!F7+'Session 8'!F12+'Session 8'!F17+'Session 8'!F22+'Session 8'!F27+'Session 8'!F32 -> 0 | G9: ='Session 8'!G2+'Session 8'!G7+'Session 8'!G12+'Session 8'!G17+'Session 8'!G22+'Session 8'!G27+'Session 8'!G32 -> 0 | H9: ='Session 8'!H2+'Session 8'!H7+'Session 8'!H12+'Session 8'!H17+'Session 8'!H22+'Session 8'!H27+'Session 8'!H32 -> 0 | I9: ='Session 8'!I2+'Session 8'!I7+'Session 8'!I12+'Session 8'!I17+'Session 8'!I22+'Session 8'!I27+'Session 8'!I32 -> 0 | ... Y9: ='Session 8'!Y2+'Session 8'!Y7+'Session 8'!Y12+'Session 8'!Y17+'Session 8'!Y22+'Session 8'!Y27+'Session 8'!Y32 -> 0 | Z9: =SUM(B9:Y9) -> 0
A10: Session 9: | B10: ='Session 9'!B2+'Session 9'!B7+'Session 9'!B12+'Session 9'!B17+'Session 9'!B22+'Session 9'!B27+'Session 9'!B32 -> 0 | C10: ='Session 9'!C2+'Session 9'!C7+'Session 9'!C12+'Session 9'!C17+'Session 9'!C22+'Session 9'!C27+'Session 9'!C32 -> 0 | D10: ='Session 9'!D2+'Session 9'!D7+'Session 9'!D12+'Session 9'!D17+'Session 9'!D22+'Session 9'!D27+'Session 9'!D32 -> 0 | E10: ='Session 9'!E2+'Session 9'!E7+'Session 9'!E12+'Session 9'!E17+'Session 9'!E22+'Session 9'!E27+'Session 9'!E32 -> 0 | F10: ='Session 9'!F2+'Session 9'!F7+'Session 9'!F12+'Session 9'!F17+'Session 9'!F22+'Session 9'!F27+'Session 9'!F32 -> 0 | G10: ='Session 9'!G2+'Session 9'!G7+'Session 9'!G12+'Session 9'!G17+'Session 9'!G22+'Session 9'!G27+'Session 9'!G32 -> 0 | H10: ='Session 9'!H2+'Session 9'!H7+'Session 9'!H12+'Session 9'!H17+'Session 9'!H22+'Session 9'!H27+'Session 9'!H32 -> 0 | I10: ='Session 9'!I2+'Session 9'!I7+'Session 9'!I12+'Session 9'!I17+'Session 9'!I22+'Session 9'!I27+'Session 9'!I32 -> 0 | ... Y10: ='Session 9'!Y2+'Session 9'!Y7+'Session 9'!Y12+'Session 9'!Y17+'Session 9'!Y22+'Session 9'!Y27+'Session 9'!Y32 -> 0 | Z10: =SUM(B10:Y10) -> 0
A11: Session 10: | B11: ='Session 10'!B2+'Session 10'!B7+'Session 10'!B12+'Session 10'!B17+'Session 10'!B22+'Session 10'!B27+'Session 10'!B32 -> 0 | C11: ='Session 10'!C2+'Session 10'!C7+'Session 10'!C12+'Session 10'!C17+'Session 10'!C22+'Session 10'!C27+'Session 10'!C32 -> 0 | D11: ='Session 10'!D2+'Session 10'!D7+'Session 10'!D12+'Session 10'!D17+'Session 10'!D22+'Session 10'!D27+'Session 10'!D32 -> 0 | E11: ='Session 10'!E2+'Session 10'!E7+'Session 10'!E12+'Session 10'!E17+'Session 10'!E22+'Session 10'!E27+'Session 10'!E32 -> 0 | F11: ='Session 10'!F2+'Session 10'!F7+'Session 10'!F12+'Session 10'!F17+'Session 10'!F22+'Session 10'!F27+'Session 10'!F32 -> 0 | G11: ='Session 10'!G2+'Session 10'!G7+'Session 10'!G12+'Session 10'!G17+'Session 10'!G22+'Session 10'!G27+'Session 10'!G32 -> 0 | H11: ='Session 10'!H2+'Session 10'!H7+'Session 10'!H12+'Session 10'!H17+'Session 10'!H22+'Session 10'!H27+'Session 10'!H32 -> 0 | I11: ='Session 10'!I2+'Session 10'!I7+'Session 10'!I12+'Session 10'!I17+'Session 10'!I22+'Session 10'!I27+'Session 10'!I32 -> 0 | ... Y11: ='Session 10'!Y2+'Session 10'!Y7+'Session 10'!Y12+'Session 10'!Y17+'Session 10'!Y22+'Session 10'!Y27+'Session 10'!Y32 -> 0 | Z11: =SUM(B11:Y11) -> 0
A12: VP Total: | B12: =SUM(B2:B11) -> 37.5 | C12: =SUM(C2:C11) -> 45 | D12: =SUM(D2:D11) -> -12.5 | E12: =SUM(E2:E11) -> -10 | F12: =SUM(F2:F11) -> -22.5 | G12: =SUM(G2:G11) -> -22.5 | H12: =SUM(H2:H11) -> 35 | I12: =SUM(I2:I11) -> -12.5 | ... Y12: =SUM(Y2:Y11) -> 0 | Z12: =SUM(B12:Y12) -> 25
A13: GP Score: | B13: 360 | C13: 1783 | D13: 2139 | F13: 630 | G13: 1386 | H13: 1826 | I13: 411 | J13: 1197
A15: Llama Points: | B15: =B13/100+B12 -> 41.1 | C15: =C13/100+C12 -> 62.83 | D15: =D13/100+D12 -> 8.89 | E15: =E13/100+E12 -> -10 | F15: =F13/100+F12 -> -16.2 | G15: =G13/100+G12 -> -8.64 | H15: =H13/100+H12 -> 53.26 | I15: =I13/100+I12 -> -8.39 | ... Y15: =Y13/100+Y12 -> 0 | Z15: =SUM(B15:Y15) -> 122.32

Sheet Session 1
B1: ='Total Score'!B1 -> Llama | C1: ='Total Score'!C1 -> Nic | D1: ='Total Score'!D1 -> Taank | E1: ='Total Score'!E1 -> Elephant | F1: ='Total Score'!F1 -> Jorg | G1: ='Total Score'!G1 -> Deadlock | H1: ='Total Score'!H1 -> Veil | I1: ='Total Score'!I1 -> Arch | ... Y1: ='Total Score'!Y1
A2: War 1: | B2: =IFERROR(10*B3*B5/(B4+1)+10*(B5-1)*((B4+1)/(2*B3)), 2*B6*(2*B5-1)) -> 20 | C2: =IFERROR(10*C3*C5/(C4+1)+10*(C5-1)*((C4+1)/(2*C3)), 2*C6*(2*C5-1)) -> 0 | D2: =IFERROR(10*D3*D5/(D4+1)+10*(D5-1)*((D4+1)/(2*D3)), 2*D6*(2*D5-1)) -> 0 | E2: =IFERROR(10*E3*E5/(E4+1)+10*(E5-1)*((E4+1)/(2*E3)), 2*E6*(2*E5-1)) -> -10 | F2: =IFERROR(10*F3*F5/(F4+1)+10*(F5-1)*((F4+1)/(2*F3)), 2*F6*(2*F5-1)) -> -10 | G2: =IFERROR(10*G3*G5/(G4+1)+10*(G5-1)*((G4+1)/(2*G3)), 2*G6*(2*G5-1)) -> 0 | H2: =IFERROR(10*H3*H5/(H4+1)+10*(H5-1)*((H4+1)/(2*H3)), 2*H6*(2*H5-1)) -> 0 | I2: =IFERROR(10*I3*I5/(I4+1)+10*(I5-1)*((I4+1)/(2*I3)), 2*I6*(2*I5-1)) -> 0 | ... Y2: =IFERROR(10*Y3*Y5/(Y4+1)+10*(Y5-1)*((Y4+1)/(2*Y3)), 2*Y6*(2*Y5-1)) -> 0
A3: # of Enemies: | B3: 2 | E3: 1 | F3: 1
A4: # of Allies: | E4: 1 | F4: 1
A5: Win? | B5: 1
A6: Condots?
A7: War 2: | B7: =IFERROR(10*B8*B10/(B9+1)+10*(B10-1)*((B9+1)/(2*B8)), 2*B11*(2*B10-1)) -> 0 | C7: =IFERROR(10*C8*C10/(C9+1)+10*(C10-1)*((C9+1)/(2*C8)), 2*C11*(2*C10-1)) -> -5 | D7: =IFERROR(10*D8*D10/(D9+1)+10*(D10-1)*((D9+1)/(2*D8)), 2*D11*(2*D10-1)) -> 10 | E7: =IFERROR(10*E8*E10/(E9+1)+10*(E10-1)*((E9+1)/(2*E8)), 2*E11*(2*E10-1)) -> 0 | F7: =IFERROR(10*F8*F10/(F9+1)+10*(F10-1)*((F9+1)/(2*F8)), 2*F11*(2*F10-1)) -> 0 | G7: =IFERROR(10*G8*G10/(G9+1)+10*(G10-1)*((G9+1)/(2*G8)), 2*G11*(2*G10-1)) -> 0 | H7: =IFERROR(10*H8*H10/(H9+1)+10*(H10-1)*((H9+1)/(2*H8)), 2*H11*(2*H10-1)) -> 0 | I7: =IFERROR(10*I8*I10/(I9+1)+10*(I10-1)*((I9+1)/(2*I8)), 2*I11*(2*I10-1)) -> 0 | ... Y7: =IFERROR(10*Y8*Y10/(Y9+1)+10*(Y10-1)*((Y9+1)/(2*Y8)), 2*Y11*(2*Y10-1)) -> 0
A8: # of Enemies: | C8: 1 | D8: 1
A9: # of Allies:
A10: Win? | D10: 1
A11: Condots?
A12: War 3: | B12: =IFERROR(10*B13*B15/(B14+1)+10*(B15-1)*((B14+1)/(2*B13)), 2*B16*(2*B15-1)) -> 0 | C12: =IFERROR(10*C13*C15/(C14+1)+10*(C15-1)*((C14+1)/(2*C13)), 2*C16*(2*C15-1)) -> 0 | D12: =IFERROR(10*D13*D15/(D14+1)+10*(D15-1)*((D14+1)/(2*D13)), 2*D16*(2*D15-1)) -> 0 | E12: =IFERROR(10*E13*E15/(E14+1)+10*(E15-1)*((E14+1)/(2*E13)), 2*E16*(2*E15-1)) -> 0 | F12: =IFERROR(10*F13*F15/(F14+1)+10*(F15-1)*((F14+1)/(2*F13)), 2*F16*(2*F15-1)) -> 0 | G12: =IFERROR(10*G13*G15/(G14+1)+10*(G15-1)*((G14+1)/(2*G13)), 2*G16*(2*G15-1)) -> 0 | H12: =IFERROR(10*H13*H15/(H14+1)+10*(H15-1)*((H14+1)/(2*H13)), 2*H16*(2*H15-1)) -> 0 | I12: =IFERROR(10*I13*I15/(I14+1)+10*(I15-1)*((I14+1)/(2*I13)), 2*I16*(2*I15-1)) -> 0 | ... Y12: =IFERROR(10*Y13*Y15/(Y14+1)+10*(Y15-1)*((Y14+1)/(2*Y13)), 2*Y16*(2*Y15-1)) -> 0
A13: # of Enemies:
A14: # of Allies:
A15: Win?
A16: Condots?
A17: War 4: | B17: =IFERROR(10*B18*B20/(B19+1)+10*(B20-1)*((B19+1)/(2*B18)), 2*B21*(2*B20-1)) -> 0 | C17: =IFERROR(10*C18*C20/(C19+1)+10*(C20-1)*((C19+1)/(2*C18)), 2*C21*(2*C20-1)) -> 0 | D17: =IFERROR(10*D18*D20/(D19+1)+10*(D20-1)*((D19+1)/(2*D18)), 2*D21*(2*D20-1)) -> 0 | E17: =IFERROR(10*E18*E20/(E19+1)+10*(E20-1)*((E19+1)/(2*E18)), 2*E21*(2*E20-1)) -> 0 | F17: =IFERROR(10*F18*F20/(F19+1)+10*(F20-1)*((F19+1)/(2*F18)), 2*F21*(2*F20-1)) -> 0 | G17: =IFERROR(10*G18*G20/(G19+1)+10*(G20-1)*((G19+1)/(2*G18)), 2*G21*(2*G20-1)) -> 0 | H17: =IFERROR(10*H18*H20/(H19+1)+10*(H20-1)*((H19+1)/(2*H18)), 2*H21*(2*H20-1)) -> 0 | I17: =IFERROR(10*I18*I20/(I19+1)+10*(I20-1)*((I19+1)/(2*I18)), 2*I21*(2*I20-1)) -> 0 | ... Y17: =IFERROR(10*Y18*Y20/(Y19+1)+10*(Y20-1)*((Y19+1)/(2*Y18)), 2*Y21*(2*Y20-1)) -> 0
A18: # of Enemies:
A19: # of Allies:
A20: Win?
A21: Condots?
A22: War 5: | B22: =IFERROR(10*B23*B25/(B24+1)+10*(B25-1)*((B24+1)/(2*B23)), 2*B26*(2*B25-1)) -> 0 | C22: =IFERROR(10*C23*C25/(C24+1)+10*(C25-1)*((C24+1)/(2*C23)), 2*C26*(2*C25-1)) -> 0 | D22: =IFERROR(10*D23*D25/(D24+1)+10*(D25-1)*((D24+1)/(2*D23)), 2*D26*(2*D25-1)) -> 0 | E22: =IFERROR(10*E23*E25/(E24+1)+10*(E25-1)*((E24+1)/(2*E23)), 2*E26*(2*E25-1)) -> 0 | F22: =IFERROR(10*F23*F25/(F24+1)+10*(F25-1)*((F24+1)/(2*F23)), 2*F26*(2*F25-1)) -> 0 | G22: =IFERROR(10*G23*G25/(G24+1)+10*(G25-1)*((G24+1)/(2*G23)), 2*G26*(2*G25-1)) -> 0 | H22: =IFERROR(10*H23*H25/(H24+1)+10*(H25-1)*((H24+1)/(2*H23)), 2*H26*(2*H25-1)) -> 0 | I22: =IFERROR(10*I23*I25/(I24+1)+10*(I25-1)*((I24+1)/(2*I23)), 2*I26*(2*I25-1)) -> 0 | ... Y22: =IFERROR(10*Y23*Y25/(Y24+1)+10*(Y25-1)*((Y24+1)/(2*Y23)), 2*Y26*(2*Y25-1)) -> 0
A23: # of Enemies:
A24: # of Allies:
A25: Win?
A26: Condots?
A27: War 6: | B27: =IFERROR(10*B28*B30/(B29+1)+10*(B30-1)*((B29+1)/(2*B28)), 2*B31*(2*B30-1)) -> 0 | C27: =IFERROR(10*C28*C30/(C29+1)+10*(C30-1)*((C29+1)/(2*C28)), 2*C31*(2*C30-1)) -> 0 | D27: =IFERROR(10*D28*D30/(D29+1)+10*(D30-1)*((D29+1)/(2*D28)), 2*D31*(2*D30-1)) -> 0 | E27: =IFERROR(10*E28*E30/(E29+1)+10*(E30-1)*((E29+1)/(2*E28)), 2*E31*(2*E30-1)) -> 0 | F27: =IFERROR(10*F28*F30/(F29+1)+10*(F30-1)*((F29+1)/(2*F28)), 2*F31*(2*F30-1)) -> 0 | G27: =IFERROR(10*G28*G30/(G29+1)+10*(G30-1)*((G29+1)/(2*G28)), 2*G31*(2*G30-1)) -> 0 | H27: =IFERROR(10*H28*H30/(H29+1)+10*(H30-1)*((H29+1)/(2*H28)), 2*H31*(2*H30-1)) -> 0 | I27: =IFERROR(10*I28*I30/(I29+1)+10*(I30-1)*((I29+1)/(2*I28)), 2*I31*(2*I30-1)) -> 0 | ... Y27: =IFERROR(10*Y28*Y30/(Y29+1)+10*(Y30-1)*((Y29+1)/(2*Y28)), 2*Y31*(2*Y30-1)) -> 0
A28: # of Enemies:
A29: # of Allies:
A30: Win?
A31: Condots?
A32: War 7: | B32: =IFERROR(10*B33*B35/(B34+1)+10*(B35-1)*((B34+1)/(2*B33)), 2*B36*(2*B35-1)) -> 0 | C32: =IFERROR(10*C33*C35/(C34+1)+10*(C35-1)*((C34+1)/(2*C33)), 2*C36*(2*C35-1)) -> 0 | D32: =IFERROR(10*D33*D35/(D34+1)+10*(D35-1)*((D34+1)/(2*D33)), 2*D36*(2*D35-1)) -> 0 | E32: =IFERROR(10*E33*E35/(E34+1)+10*(E35-1)*((E34+1)/(2*E33)), 2*E36*(2*E35-1)) -> 0 | F32: =IFERROR(10*F33*F35/(F34+1)+10*(F35-1)*((F34+1)/(2*F33)), 2*F36*(2*F35-1)) -> 0 | G32: =IFERROR(10*G33*G35/(G34+1)+10*(G35-1)*((G34+1)/(2*G33)), 2*G36*(2*G35-1)) -> 0 | H32: =IFERROR(10*H33*H35/(H34+1)+10*(H35-1)*((H34+1)/(2*H33)), 2*H36*(2*H35-1)) -> 0 | I32: =IFERROR(10*I33*I35/(I34+1)+10*(I35-1)*((I34+1)/(2*I33)), 2*I36*(2*I35-1)) -> 0 | ... Y32: =IFERROR(10*Y33*Y35/(Y34+1)+10*(Y35-1)*((Y34+1)/(2*Y33)), 2*Y36*(2*Y35-1)) -> 0
A33: # of Enemies:
A34: # of Allies:
A35: Win?
A36: Condots?

Sheet Session 2
B1: ='Total Score'!B1 -> Llama | C1: ='Total Score'!C1 -> Nic | D1: ='Total Score'!D1 -> Taank | E1: ='Total Score'!E1 -> Elephant | F1: ='Total Score'!F1 -> Jorg | G1: ='Total Score'!G1 -> Deadlock | H1: ='Total Score'!H1 -> Veil | I1: ='Total Score'!I1 -> Arch | ... Y1: ='Total Score'!Y1
A2: War 1: | B2: =IFERROR(10*B3*B5/(B4+1)+10*(B5-1)*((B4+1)/(2*B3)), 2*B6*(2*B5-1)) -> 0 | C2: =IFERROR(10*C3*C5/(C4+1)+10*(C5-1)*((C4+1)/(2*C3)), 2*C6*(2*C5-1)) -> 10 | D2: =IFERROR(10*D3*D5/(D4+1)+10*(D5-1)*((D4+1)/(2*D3)), 2*D6*(2*D5-1)) -> -5 | E2: =IFERROR(10*E3*E5/(E4+1)+10*(E5-1)*((E4+1)/(2*E3)), 2*E6*(2*E5-1)) -> 0 | F2: =IFERROR(10*F3*F5/(F4+1)+10*(F5-1)*((F4+1)/(2*F3)), 2*F6*(2*F5-1)) -> 0 | G2: =IFERROR(10*G3*G5/(G4+1)+10*(G5-1)*((G4+1)/(2*G3)), 2*G6*(2*G5-1)) -> 0 | H2: =IFERROR(10*H3*H5/(H4+1)+10*(H5-1)*((H4+1)/(2*H3)), 2*H6*(2*H5-1)) -> 0 | I2: =IFERROR(10*I3*I5/(I4+1)+10*(I5-1)*((I4+1)/(2*I3)), 2*I6*(2*I5-1)) -> 0 | ... Z2: =IFERROR(10*Z3*Z5/(Z4+1)+10*(Z5-1)*((Z4+1)/(2*Z3)), 2*Z6*(2*Z5-1)) -> 0
A3: # of Enemies: | C3: 1 | D3: 1
A4: # of Allies:
A5: Win? | C5: 1
A6: Condots?
A7: War 2: | B7: =IFERROR(10*B8*B10/(B9+1)+10*(B10-1)*((B9+1)/(2*B8)), 2*B11*(2*B10-1)) -> 10 | C7: =IFERROR(10*C8*C10/(C9+1)+10*(C10-1)*((C9+1)/(2*C8)), 2*C11*(2*C10-1)) -> 0 | D7: =IFERROR(10*D8*D10/(D9+1)+10*(D10-1)*((D9+1)/(2*D8)), 2*D11*(2*D10-1)) -> 0 | E7: =IFERROR(10*E8*E10/(E9+1)+10*(E10-1)*((E9+1)/(2*E8)), 2*E11*(2*E10-1)) -> 0 | F7: =IFERROR(10*F8*F10/(#REF!+1)+10*(F10-1)*((#REF!+1)/(2*F8)), 2*F11*(2*F10-1)) -> 0 | G7: =IFERROR(10*G8*G10/(F9+1)+10*(G10-1)*((F9+1)/(2*G8)), 2*G11*(2*G10-1)) -> -5 | H7: =IFERROR(10*H8*H10/(H9+1)+10*(H10-1)*((H9+1)/(2*H8)), 2*H11*(2*H10-1)) -> 0 | I7: =IFERROR(10*I8*I10/(I9+1)+10*(I10-1)*((I9+1)/(2*I8)), 2*I11*(2*I10-1)) -> 0 | J7: =IFERROR(10*J8*J10/(J9+1)+10*(J10-1)*((J9+1)/(2*J8)), 2*J11*(2*J10-1)) -> 0 | K7: =IFERROR(10*K8*K10/(K9+1)+10*(K10-1)*((K9+1)/(2*K8)), 2*K11*(2*K10-1)) -> 0 | L7: =IFERROR(10*L8*L10/(L9+1)+10*(L10-1)*((L9+1)/(2*L8)), 2*L11*(2*L10-1)) -> 0 | M7: =IFERROR(10*M8*M10/(M9+1)+10*(M10-1)*((M9+1)/(2*M8)), 2*M11*(2*M10-1)) -> 0 | N7: =IFERROR(10*N8*N10/(N9+1)+10*(N10-1)*((N9+1)/(2*N8)), 2*N11*(2*N10-1)) -> 0 | O7: =IFERROR(10*O8*O10/(O9+1)+10*(O10-1)*((O9+1)/(2*O8)), 2*O11*(2*O10-1)) -> 0 | ... Y7: =IFERROR(10*Y8*Y10/(Y9+1)+10*(Y10-1)*((Y9+1)/(2*Y8)), 2*Y11*(2*Y10-1)) -> 0
A8: # of Enemies: | B8: 1 | G8: 1
A9: # of Allies:
A10: Win? | B10: 1
A11: Condots?
A12: War 3: | B12: =IFERROR(10*B13*B15/(B14+1)+10*(B15-1)*((B14+1)/(2*B13)), 2*B16*(2*B15-1)) -> 10 | C12: =IFERROR(10*C13*C15/(C14+1)+10*(C15-1)*((C14+1)/(2*C13)), 2*C16*(2*C15-1)) -> 0 | D12: =IFERROR(10*D13*D15/(D14+1)+10*(D15-1)*((D14+1)/(2*D13)), 2*D16*(2*D15-1)) -> 0 | E12: =IFERROR(10*E13*E15/(E14+1)+10*(E15-1)*((E14+1)/(2*E13)), 2*E16*(2*E15-1)) -> 0 | F12: =IFERROR(10*F13*F15/(F14+1)+10*(F15-1)*((F14+1)/(2*F13)), 2*F16*(2*F15-1)) -> 0 | G12: =IFERROR(10*G13*G15/(G14+1)+10*(G15-1)*((G14+1)/(2*G13)), 2*G16*(2*G15-1)) -> -5 | H12: =IFERROR(10*H13*H15/(H14+1)+10*(H15-1)*((H14+1)/(2*H13)), 2*H16*(2*H15-1)) -> 0 | I12: =IFERROR(10*I13*I15/(I14+1)+10*(I15-1)*((I14+1)/(2*I13)), 2*I16*(2*I15-1)) -> 0 | ... Y12: =IFERROR(10*Y13*Y15/(Y14+1)+10*(Y15-1)*((Y14+1)/(2*Y13)), 2*Y16*(2*Y15-1)) -> 0
A13: # of Enemies: | B13: 1 | G13: 1
A14: # of Allies:
A15: Win? | B15: 1
A16: Condots?
A17: War 4: | B17: =IFERROR(10*B18*B20/(B19+1)+10*(B20-1)*((B19+1)/(2*B18)), 2*B21*(2*B20-1)) -> 0 | C17: =IFERROR(10*C18*C20/(C19+1)+10*(C20-1)*((C19+1)/(2*C18)), 2*C21*(2*C20-1)) -> 0 | D17: =IFERROR(10*D18*D20/(D19+1)+10*(D20-1)*((D19+1)/(2*D18)), 2*D21*(2*D20-1)) -> 0 | E17: =IFERROR(10*E18*E20/(E19+1)+10*(E20-1)*((E19+1)/(2*E18)), 2*E21*(2*E20-1)) -> 0 | F17: =IFERROR(10*F18*F20/(F19+1)+10*(F20-1)*((F19+1)/(2*F18)), 2*F21*(2*F20-1)) -> 0 | G17: =IFERROR(10*G18*G20/(G19+1)+10*(G20-1)*((G19+1)/(2*G18)), 2*G21*(2*G20-1)) -> 0 | H17: =IFERROR(10*H18*H20/(H19+1)+10*(H20-1)*((H19+1)/(2*H18)), 2*H21*(2*H20-1)) -> 0 | I17: =IFERROR(10*I18*I20/(I19+1)+10*(I20-1)*((I19+1)/(2*I18)), 2*I21*(2*I20-1)) -> 0 | ... Y17: =IFERROR(10*Y18*Y20/(Y19+1)+10*(Y20-1)*((Y19+1)/(2*Y18)), 2*Y21*(2*Y20-1)) -> 0
A18: # of Enemies:
A19: # of Allies:
A20: Win?
A21: Condots?
A22: War 5: | B22: =IFERROR(10*B23*B25/(B24+1)+10*(B25-1)*((B24+1)/(2*B23)), 2*B26*(2*B25-1)) -> 0 | C22: =IFERROR(10*C23*C25/(C24+1)+10*(C25-1)*((C24+1)/(2*C23)), 2*C26*(2*C25-1)) -> 0 | D22: =IFERROR(10*D23*D25/(D24+1)+10*(D25-1)*((D24+1)/(2*D23)), 2*D26*(2*D25-1)) -> 0 | E22: =IFERROR(10*E23*E25/(E24+1)+10*(E25-1)*((E24+1)/(2*E23)), 2*E26*(2*E25-1)) -> 0 | F22: =IFERROR(10*F23*F25/(F24+1)+10*(F25-1)*((F24+1)/(2*F23)), 2*F26*(2*F25-1)) -> 0 | G22: =IFERROR(10*G23*G25/(G24+1)+10*(G25-1)*((G24+1)/(2*G23)), 2*G26*(2*G25-1)) -> 0 | H22: =IFERROR(10*H23*H25/(H24+1)+10*(H25-1)*((H24+1)/(2*H23)), 2*H26*(2*H25-1)) -> 0 | I22: =IFERROR(10*I23*I25/(I24+1)+10*(I25-1)*((I24+1)/(2*I23)), 2*I26*(2*I25-1)) -> 0 | ... Y22: =IFERROR(10*Y23*Y25/(Y24+1)+10*(Y25-1)*((Y24+1)/(2*Y23)), 2*Y26*(2*Y25-1)) -> 0
A23: # of Enemies:
A24: # of Allies:
A25: Win?
A26: Condots?
A27: War 6: | B27: =IFERROR(10*B28*B30/(B29+1)+10*(B30-1)*((B29+1)/(2*B28)), 2*B31*(2*B30-1)) -> 0 | C27: =IFERROR(10*C28*C30/(C29+1)+10*(C30-1)*((C29+1)/(2*C28)), 2*C31*(2*C30-1)) -> 0 | D27: =IFERROR(10*D28*D30/(D29+1)+10*(D30-1)*((D29+1)/(2*D28)), 2*D31*(2*D30-1)) -> 0 | E27: =IFERROR(10*E28*E30/(E29+1)+10*(E30-1)*((E29+1)/(2*E28)), 2*E31*(2*E30-1)) -> 0 | F27: =IFERROR(10*F28*F30/(F29+1)+10*(F30-1)*((F29+1)/(2*F28)), 2*F31*(2*F30-1)) -> 0 | G27: =IFERROR(10*G28*G30/(G29+1)+10*(G30-1)*((G29+1)/(2*G28)), 2*G31*(2*G30-1)) -> 0 | H27: =IFERROR(10*H28*H30/(H29+1)+10*(H30-1)*((H29+1)/(2*H28)), 2*H31*(2*H30-1)) -> 0 | I27: =IFERROR(10*I28*I30/(I29+1)+10*(I30-1)*((I29+1)/(2*I28)), 2*I31*(2*I30-1)) -> 0 | ... Y27: =IFERROR(10*Y28*Y30/(Y29+1)+10*(Y30-1)*((Y29+1)/(2*Y28)), 2*Y31*(2*Y30-1)) -> 0
A28: # of Enemies:
A29: # of Allies:
A30: Win?
A31: Condots?
A32: War 7: | B32: =IFERROR(10*B33*((B36-2)/-2)*B35/(B34+1)+10*(B36+1)*(B35-1)*((B34+1)/(2*B33)), 0) -> 0 | C32: =IFERROR(10*C33*C35/(C34+1)+10*(C35-1)*((C34+1)/(2*C33)), 2*C36*(2*C35-1)) -> 0 | D32: =IFERROR(10*D33*D35/(D34+1)+10*(D35-1)*((D34+1)/(2*D33)), 2*D36*(2*D35-1)) -> 0 | E32: =IFERROR(10*E33*E35/(E34+1)+10*(E35-1)*((E34+1)/(2*E33)), 2*E36*(2*E35-1)) -> 0 | F32: =IFERROR(10*F33*F35/(F34+1)+10*(F35-1)*((F34+1)/(2*F33)), 2*F36*(2*F35-1)) -> 0 | G32: =IFERROR(10*G33*G35/(G34+1)+10*(G35-1)*((G34+1)/(2*G33)), 2*G36*(2*G35-1)) -> 0 | H32: =IFERROR(10*H33*H35/(H34+1)+10*(H35-1)*((H34+1)/(2*H33)), 2*H36*(2*H35-1)) -> 0 | I32: =IFERROR(10*I33*I35/(I34+1)+10*(I35-1)*((I34+1)/(2*I33)), 2*I36*(2*I35-1)) -> 0 | J32: =IFERROR(10*J33*J35/(J34+1)+10*(J35-1)*((J34+1)/(2*J33)), 2*J36*(2*J35-1)) -> 0 | ... Z32: =IFERROR(10*Z33*Z35/(Z34+1)+10*(Z35-1)*((Z34+1)/(2*Z33)), 2*Z36*(2*Z35-1)) -> 0
A33: # of Enemies:
A34: # of Allies:
A35: Win?
A36: Condots?

Sheet Session 3
B1: ='Total Score'!B1 -> Llama | C1: ='Total Score'!C1 -> Nic | D1: ='Total Score'!D1 -> Taank | E1: ='Total Score'!E1 -> Elephant | F1: ='Total Score'!F1 -> Jorg | G1: ='Total Score'!G1 -> Deadlock | H1: ='Total Score'!H1 -> Veil | I1: ='Total Score'!I1 -> Arch | ... Y1: ='Total Score'!Y1
A2: War 1: | B2: =IFERROR(10*B3*B5/(B4+1)+10*(B5-1)*((B4+1)/(2*B3)), 2*B6*(2*B5-1)) -> 0 | C2: =IFERROR(10*C3*C5/(C4+1)+10*(C5-1)*((C4+1)/(2*C3)), 2*C6*(2*C5-1)) -> 10 | D2: =IFERROR(10*D3*D5/(D4+1)+10*(D5-1)*((D4+1)/(2*D3)), 2*D6*(2*D5-1)) -> -5 | E2: =IFERROR(10*E3*E5/(E4+1)+10*(E5-1)*((E4+1)/(2*E3)), 2*E6*(2*E5-1)) -> 0 | F2: =IFERROR(10*F3*F5/(F4+1)+10*(F5-1)*((F4+1)/(2*F3)), 2*F6*(2*F5-1)) -> 0 | G2: =IFERROR(10*G3*G5/(G4+1)+10*(G5-1)*((G4+1)/(2*G3)), 2*G6*(2*G5-1)) -> 0 | H2: =IFERROR(10*H3*H5/(H4+1)+10*(H5-1)*((H4+1)/(2*H3)), 2*H6*(2*H5-1)) -> 0 | I2: =IFERROR(10*I3*I5/(I4+1)+10*(I5-1)*((I4+1)/(2*I3)), 2*I6*(2*I5-1)) -> 0 | ... Y2: =IFERROR(10*Y3*Y5/(Y4+1)+10*(Y5-1)*((Y4+1)/(2*Y3)), 2*Y6*(2*Y5-1)) -> 0
A3: # of Enemies: | C3: 1 | D3: 1
A4: # of Allies:
A5: Win? | C5: 1
A6: Condots?
A7: War 2: | B7: =IFERROR(10*B8*B10/(B9+1)+10*(B10-1)*((B9+1)/(2*B8)), 2*B11*(2*B10-1)) -> 0 | C7: =IFERROR(10*C8*C10/(C9+1)+10*(C10-1)*((C9+1)/(2*C8)), 2*C11*(2*C10-1)) -> 0 | D7: =IFERROR(10*D8*D10/(D9+1)+10*(D10-1)*((D9+1)/(2*D8)), 2*D11*(2*D10-1)) -> -5 | E7: =IFERROR(10*E8*E10/(E9+1)+10*(E10-1)*((E9+1)/(2*E8)), 2*E11*(2*E10-1)) -> 0 | F7: =IFERROR(10*F8*F10/(F9+1)+10*(F10-1)*((F9+1)/(2*F8)), 2*F11*(2*F10-1)) -> 0 | G7: =IFERROR(10*G8*G10/(G9+1)+10*(G10-1)*((G9+1)/(2*G8)), 2*G11*(2*G10-1)) -> 0 | H7: =IFERROR(10*H8*H10/(H9+1)+10*(H10-1)*((H9+1)/(2*H8)), 2*H11*(2*H10-1)) -> 10 | I7: =IFERROR(10*I8*I10/(I9+1)+10*(I10-1)*((I9+1)/(2*I8)), 2*I11*(2*I10-1)) -> 0 | ... Y7: =IFERROR(10*Y8*Y10/(Y9+1)+10*(Y10-1)*((Y9+1)/(2*Y8)), 2*Y11*(2*Y10-1)) -> 0
A8: # of Enemies: | D8: 1 | H8: 1
A9: # of Allies:
A10: Win? | H10: 1
A11: Condots?
A12: War 3: | B12: =IFERROR(10*B13*B15/(B14+1)+10*(B15-1)*((B14+1)/(2*B13)), 2*B16*(2*B15-1)) -> 0 | C12: =IFERROR(10*C13*C15/(C14+1)+10*(C15-1)*((C14+1)/(2*C13)), 2*C16*(2*C15-1)) -> 0 | D12: =IFERROR(10*D13*D15/(D14+1)+10*(D15-1)*((D14+1)/(2*D13)), 2*D16*(2*D15-1)) -> 0 | E12: =IFERROR(10*E13*E15/(E14+1)+10*(E15-1)*((E14+1)/(2*E13)), 2*E16*(2*E15-1)) -> 0 | F12: =IFERROR(10*F13*F15/(F14+1)+10*(F15-1)*((F14+1)/(2*F13)), 2*F16*(2*F15-1)) -> 0 | G12: =IFERROR(10*G13*G15/(G14+1)+10*(G15-1)*((G14+1)/(2*G13)), 2*G16*(2*G15-1)) -> 0 | H12: =IFERROR(10*H13*H15/(H14+1)+10*(H15-1)*((H14+1)/(2*H13)), 2*H16*(2*H15-1)) -> 0 | I12: =IFERROR(10*I13*I15/(I14+1)+10*(I15-1)*((I14+1)/(2*I13)), 2*I16*(2*I15-1)) -> 0 | ... Y12: =IFERROR(10*Y13*Y15/(Y14+1)+10*(Y15-1)*((Y14+1)/(2*Y13)), 2*Y16*(2*Y15-1)) -> 0
A13: # of Enemies:
A14: # of Allies:
A15: Win?
A16: Condots?
A17: War 4: | B17: =IFERROR(10*B18*B20/(B19+1)+10*(B20-1)*((B19+1)/(2*B18)), 2*B21*(2*B20-1)) -> 0 | C17: =IFERROR(10*C18*C20/(C19+1)+10*(C20-1)*((C19+1)/(2*C18)), 2*C21*(2*C20-1)) -> 0 | D17: =IFERROR(10*D18*D20/(D19+1)+10*(D20-1)*((D19+1)/(2*D18)), 2*D21*(2*D20-1)) -> 0 | E17: =IFERROR(10*E18*E20/(E19+1)+10*(E20-1)*((E19+1)/(2*E18)), 2*E21*(2*E20-1)) -> 0 | F17: =IFERROR(10*F18*F20/(F19+1)+10*(F20-1)*((F19+1)/(2*F18)), 2*F21*(2*F20-1)) -> 0 | G17: =IFERROR(10*G18*G20/(G19+1)+10*(G20-1)*((G19+1)/(2*G18)), 2*G21*(2*G20-1)) -> 0 | H17: =IFERROR(10*H18*H20/(H19+1)+10*(H20-1)*((H19+1)/(2*H18)), 2*H21*(2*H20-1)) -> 0 | I17: =IFERROR(10*I18*I20/(I19+1)+10*(I20-1)*((I19+1)/(2*I18)), 2*I21*(2*I20-1)) -> 0 | ... Y17: =IFERROR(10*Y18*Y20/(Y19+1)+10*(Y20-1)*((Y19+1)/(2*Y18)), 2*Y21*(2*Y20-1)) -> 0
A18: # of Enemies:
A19: # of Allies:
A20: Win?
A21: Condots?
A22: War 5: | B22: =IFERROR(10*B23*B25/(B24+1)+10*(B25-1)*((B24+1)/(2*B23)), 2*B26*(2*B25-1)) -> 0 | C22: =IFERROR(10*C23*C25/(C24+1)+10*(C25-1)*((C24+1)/(2*C23)), 2*C26*(2*C25-1)) -> 0 | D22: =IFERROR(10*D23*D25/(D24+1)+10*(D25-1)*((D24+1)/(2*D23)), 2*D26*(2*D25-1)) -> 0 | E22: =IFERROR(10*E23*E25/(E24+1)+10*(E25-1)*((E24+1)/(2*E23)), 2*E26*(2*E25-1)) -> 0 | F22: =IFERROR(10*F23*F25/(F24+1)+10*(F25-1)*((F24+1)/(2*F23)), 2*F26*(2*F25-1)) -> 0 | G22: =IFERROR(10*G23*G25/(G24+1)+10*(G25-1)*((G24+1)/(2*G23)), 2*G26*(2*G25-1)) -> 0 | H22: =IFERROR(10*H23*H25/(H24+1)+10*(H25-1)*((H24+1)/(2*H23)), 2*H26*(2*H25-1)) -> 0 | I22: =IFERROR(10*I23*I25/(I24+1)+10*(I25-1)*((I24+1)/(2*I23)), 2*I26*(2*I25-1)) -> 0 | ... Y22: =IFERROR(10*Y23*Y25/(Y24+1)+10*(Y25-1)*((Y24+1)/(2*Y23)), 2*Y26*(2*Y25-1)) -> 0
A23: # of Enemies:
A24: # of Allies:
A25: Win?
A26: Condots?
A27: War 6: | B27: =IFERROR(10*B28*B30/(B29+1)+10*(B30-1)*((B29+1)/(2*B28)), 2*B31*(2*B30-1)) -> 0 | C27: =IFERROR(10*C28*C30/(C29+1)+10*(C30-1)*((C29+1)/(2*C28)), 2*C31*(2*C30-1)) -> 0 | D27: =IFERROR(10*D28*D30/(D29+1)+10*(D30-1)*((D29+1)/(2*D28)), 2*D31*(2*D30-1)) -> 0 | E27: =IFERROR(10*E28*E30/(E29+1)+10*(E30-1)*((E29+1)/(2*E28)), 2*E31*(2*E30-1)) -> 0 | F27: =IFERROR(10*F28*F30/(F29+1)+10*(F30-1)*((F29+1)/(2*F28)), 2*F31*(2*F30-1)) -> 0 | G27: =IFERROR(10*G28*G30/(G29+1)+10*(G30-1)*((G29+1)/(2*G28)), 2*G31*(2*G30-1)) -> 0 | H27: =IFERROR(10*H28*H30/(H29+1)+10*(H30-1)*((H29+1)/(2*H28)), 2*H31*(2*H30-1)) -> 0 | I27: =IFERROR(10*I28*I30/(I29+1)+10*(I30-1)*((I29+1)/(2*I28)), 2*I31*(2*I30-1)) -> 0 | ... Y27: =IFERROR(10*Y28*Y30/(Y29+1)+10*(Y30-1)*((Y29+1)/(2*Y28)), 2*Y31*(2*Y30-1)) -> 0
A28: # of Enemies:
A29: # of Allies:
A30: Win?
A31: Condots?
A32: War 7: | B32: =IFERROR(10*B33*B35/(B34+1)+10*(B35-1)*((B34+1)/(2*B33)), 2*B36*(2*B35-1)) -> 0 | C32: =IFERROR(10*C33*C35/(C34+1)+10*(C35-1)*((C34+1)/(2*C33)), 2*C36*(2*C35-1)) -> 0 | D32: =IFERROR(10*D33*D35/(D34+1)+10*(D35-1)*((D34+1)/(2*D33)), 2*D36*(2*D35-1)) -> 0 | E32: =IFERROR(10*E33*E35/(E34+1)+10*(E35-1)*((E34+1)/(2*E33)), 2*E36*(2*E35-1)) -> 0 | F32: =IFERROR(10*F33*F35/(F34+1)+10*(F35-1)*((F34+1)/(2*F33)), 2*F36*(2*F35-1)) -> 0 | G32: =IFERROR(10*G33*G35/(G34+1)+10*(G35-1)*((G34+1)/(2*G33)), 2*G36*(2*G35-1)) -> 0 | H32: =IFERROR(10*H33*H35/(H34+1)+10*(H35-1)*((H34+1)/(2*H33)), 2*H36*(2*H35-1)) -> 0 | I32: =IFERROR(10*I33*I35/(I34+1)+10*(I35-1)*((I34+1)/(2*I33)), 2*I36*(2*I35-1)) -> 0 | ... Y32: =IFERROR(10*Y33*Y35/(Y34+1)+10*(Y35-1)*((Y34+1)/(2*Y33)), 2*Y36*(2*Y35-1)) -> 0
A33: # of Enemies:
A34: # of Allies:
A35: Win?
A36: Condots?

Sheet Session 4
B1: ='Total Score'!B1 -> Llama | C1: ='Total Score'!C1 -> Nic | D1: ='Total Score'!D1 -> Taank | E1: ='Total Score'!E1 -> Elephant | F1: ='Total Score'!F1 -> Jorg | G1: ='Total Score'!G1 -> Deadlock | H1: ='Total Score'!H1 -> Veil | I1: ='Total Score'!I1 -> Arch | ... Y1: ='Total Score'!Y1
A2: War 1: | B2: =IFERROR(10*B3*B5/(B4+1)+10*(B5-1)*((B4+1)/(2*B3)), 2*B6*(2*B5-1)) -> -2.5 | C2: =IFERROR(10*C3*C5/(C4+1)+10*(C5-1)*((C4+1)/(2*C3)), 2*C6*(2*C5-1)) -> 5 | D2: =IFERROR(10*D3*D5/(D4+1)+10*(D5-1)*((D4+1)/(2*D3)), 2*D6*(2*D5-1)) -> 5 | E2: =IFERROR(10*E3*E5/(E4+1)+10*(E5-1)*((E4+1)/(2*E3)), 2*E6*(2*E5-1)) -> 0 | F2: =IFERROR(10*F3*F5/(F4+1)+10*(F5-1)*((F4+1)/(2*F3)), 2*F6*(2*F5-1)) -> 0 | G2: =IFERROR(10*G3*G5/(G4+1)+10*(G5-1)*((G4+1)/(2*G3)), 2*G6*(2*G5-1)) -> 0 | H2: =IFERROR(10*H3*H5/(H4+1)+10*(H5-1)*((H4+1)/(2*H3)), 2*H6*(2*H5-1)) -> 0 | I2: =IFERROR(10*I3*I5/(I4+1)+10*(I5-1)*((I4+1)/(2*I3)), 2*I6*(2*I5-1)) -> 0 | ... Y2: =IFERROR(10*Y3*Y5/(Y4+1)+10*(Y5-1)*((Y4+1)/(2*Y3)), 2*Y6*(2*Y5-1)) -> 0
A3: # of Enemies: | B3: 2 | C3: 1 | D3: 1
A4: # of Allies: | C4: 1 | D4: 1
A5: Win? | C5: 1 | D5: 1
A6: Condots?
A7: War 2: | B7: =IFERROR(10*B8*B10/(B9+1)+10*(B10-1)*((B9+1)/(2*B8)), 2*B11*(2*B10-1)) -> 0 | C7: =IFERROR(10*C8*C10/(C9+1)+10*(C10-1)*((C9+1)/(2*C8)), 2*C11*(2*C10-1)) -> 25 | D7: =IFERROR(10*D8*D10/(D9+1)+10*(D10-1)*((D9+1)/(2*D8)), 2*D11*(2*D10-1)) -> -12.5 | E7: =IFERROR(10*E8*E10/(E9+1)+10*(E10-1)*((E9+1)/(2*E8)), 2*E11*(2*E10-1)) -> 0 | F7: =IFERROR(10*F8*F10/(F9+1)+10*(F10-1)*((F9+1)/(2*F8)), 2*F11*(2*F10-1)) -> -12.5 | G7: =IFERROR(10*G8*G10/(G9+1)+10*(G10-1)*((G9+1)/(2*G8)), 2*G11*(2*G10-1)) -> -12.5 | H7: =IFERROR(10*H8*H10/(H9+1)+10*(H10-1)*((H9+1)/(2*H8)), 2*H11*(2*H10-1)) -> 25 | I7: =IFERROR(10*I8*I10/(I9+1)+10*(I10-1)*((I9+1)/(2*I8)), 2*I11*(2*I10-1)) -> -12.5 | ... Y7: =IFERROR(10*Y8*Y10/(Y9+1)+10*(Y10-1)*((Y9+1)/(2*Y8)), 2*Y11*(2*Y10-1)) -> 0
A8: # of Enemies: | C8: 5 | D8: 2 | F8: 2 | G8: 2 | H8: 5 | I8: 2 | J8: 2
A9: # of Allies: | C9: 1 | D9: 4 | F9: 4 | G9: 4 | H9: 1 | I9: 4 | J9: 4
A10: Win? | C10: 1 | H10: 1
A11: Condots?
A12: War 3: | B12: =IFERROR(10*B13*B15/(B14+1)+10*(B15-1)*((B14+1)/(2*B13)), 2*B16*(2*B15-1)) -> 0 | C12: =IFERROR(10*C13*C15/(C14+1)+10*(C15-1)*((C14+1)/(2*C13)), 2*C16*(2*C15-1)) -> 0 | D12: =IFERROR(10*D13*D15/(D14+1)+10*(D15-1)*((D14+1)/(2*D13)), 2*D16*(2*D15-1)) -> 0 | E12: =IFERROR(10*E13*E15/(E14+1)+10*(E15-1)*((E14+1)/(2*E13)), 2*E16*(2*E15-1)) -> 0 | F12: =IFERROR(10*F13*F15/(F14+1)+10*(F15-1)*((F14+1)/(2*F13)), 2*F16*(2*F15-1)) -> 0 | G12: =IFERROR(10*G13*G15/(G14+1)+10*(G15-1)*((G14+1)/(2*G13)), 2*G16*(2*G15-1)) -> 0 | H12: =IFERROR(10*H13*H15/(H14+1)+10*(H15-1)*((H14+1)/(2*H13)), 2*H16*(2*H15-1)) -> 0 | I12: =IFERROR(10*I13*I15/(I14+1)+10*(I15-1)*((I14+1)/(2*I13)), 2*I16*(2*I15-1)) -> 0 | ... Y12: =IFERROR(10*Y13*Y15/(Y14+1)+10*(Y15-1)*((Y14+1)/(2*Y13)), 2*Y16*(2*Y15-1)) -> 0
A13: # of Enemies:
A14: # of Allies:
A15: Win?
A16: Condots?
A17: War 4: | B17: =IFERROR(10*B18*B20/(B19+1)+10*(B20-1)*((B19+1)/(2*B18)), 2*B21*(2*B20-1)) -> 0 | C17: =IFERROR(10*C18*C20/(C19+1)+10*(C20-1)*((C19+1)/(2*C18)), 2*C21*(2*C20-1)) -> 0 | D17: =IFERROR(10*D18*D20/(D19+1)+10*(D20-1)*((D19+1)/(2*D18)), 2*D21*(2*D20-1)) -> 0 | E17: =IFERROR(10*E18*E20/(E19+1)+10*(E20-1)*((E19+1)/(2*E18)), 2*E21*(2*E20-1)) -> 0 | F17: =IFERROR(10*F18*F20/(F19+1)+10*(F20-1)*((F19+1)/(2*F18)), 2*F21*(2*F20-1)) -> 0 | G17: =IFERROR(10*G18*G20/(G19+1)+10*(G20-1)*((G19+1)/(2*G18)), 2*G21*(2*G20-1)) -> 0 | H17: =IFERROR(10*H18*H20/(H19+1)+10*(H20-1)*((H19+1)/(2*H18)), 2*H21*(2*H20-1)) -> 0 | I17: =IFERROR(10*I18*I20/(I19+1)+10*(I20-1)*((I19+1)/(2*I18)), 2*I21*(2*I20-1)) -> 0 | ... Y17: =IFERROR(10*Y18*Y20/(Y19+1)+10*(Y20-1)*((Y19+1)/(2*Y18)), 2*Y21*(2*Y20-1)) -> 0
A18: # of Enemies:
A19: # of Allies:
A20: Win?
A21: Condots?
A22: War 5: | B22: =IFERROR(10*B23*B25/(B24+1)+10*(B25-1)*((B24+1)/(2*B23)), 2*B26*(2*B25-1)) -> 0 | C22: =IFERROR(10*C23*C25/(C24+1)+10*(C25-1)*((C24+1)/(2*C23)), 2*C26*(2*C25-1)) -> 0 | D22: =IFERROR(10*D23*D25/(D24+1)+10*(D25-1)*((D24+1)/(2*D23)), 2*D26*(2*D25-1)) -> 0 | E22: =IFERROR(10*E23*E25/(E24+1)+10*(E25-1)*((E24+1)/(2*E23)), 2*E26*(2*E25-1)) -> 0 | F22: =IFERROR(10*F23*F25/(F24+1)+10*(F25-1)*((F24+1)/(2*F23)), 2*F26*(2*F25-1)) -> 0 | G22: =IFERROR(10*G23*G25/(G24+1)+10*(G25-1)*((G24+1)/(2*G23)), 2*G26*(2*G25-1)) -> 0 | H22: =IFERROR(10*H23*H25/(H24+1)+10*(H25-1)*((H24+1)/(2*H23)), 2*H26*(2*H25-1)) -> 0 | I22: =IFERROR(10*I23*I25/(I24+1)+10*(I25-1)*((I24+1)/(2*I23)), 2*I26*(2*I25-1)) -> 0 | ... Y22: =IFERROR(10*Y23*Y25/(Y24+1)+10*(Y25-1)*((Y24+1)/(2*Y23)), 2*Y26*(2*Y25-1)) -> 0
A23: # of Enemies:
A24: # of Allies:
A25: Win?
A26: Condots?
A27: War 6: | B27: =IFERROR(10*B28*B30/(B29+1)+10*(B30-1)*((B29+1)/(2*B28)), 2*B31*(2*B30-1)) -> 0 | C27: =IFERROR(10*C28*C30/(C29+1)+10*(C30-1)*((C29+1)/(2*C28)), 2*C31*(2*C30-1)) -> 0 | D27: =IFERROR(10*D28*D30/(D29+1)+10*(D30-1)*((D29+1)/(2*D28)), 2*D31*(2*D30-1)) -> 0 | E27: =IFERROR(10*E28*E30/(E29+1)+10*(E30-1)*((E29+1)/(2*E28)), 2*E31*(2*E30-1)) -> 0 | F27: =IFERROR(10*F28*F30/(F29+1)+10*(F30-1)*((F29+1)/(2*F28)), 2*F31*(2*F30-1)) -> 0 | G27: =IFERROR(10*G28*G30/(G29+1)+10*(G30-1)*((G29+1)/(2*G28)), 2*G31*(2*G30-1)) -> 0 | H27: =IFERROR(10*H28*H30/(H29+1)+10*(H30-1)*((H29+1)/(2*H28)), 2*H31*(2*H30-1)) -> 0 | I27: =IFERROR(10*I28*I30/(I29+1)+10*(I30-1)*((I29+1)/(2*I28)), 2*I31*(2*I30-1)) -> 0 | ... Y27: =IFERROR(10*Y28*Y30/(Y29+1)+10*(Y30-1)*((Y29+1)/(2*Y28)), 2*Y31*(2*Y30-1)) -> 0
A28: # of Enemies:
A29: # of Allies:
A30: Win?
A31: Condots?
A32: War 7: | B32: =IFERROR(10*B33*B35/(B34+1)+10*(B35-1)*((B34+1)/(2*B33)), 2*B36*(2*B35-1)) -> 0 | C32: =IFERROR(10*C33*C35/(C34+1)+10*(C35-1)*((C34+1)/(2*C33)), 2*C36*(2*C35-1)) -> 0 | D32: =IFERROR(10*D33*D35/(D34+1)+10*(D35-1)*((D34+1)/(2*D33)), 2*D36*(2*D35-1)) -> 0 | E32: =IFERROR(10*E33*E35/(E34+1)+10*(E35-1)*((E34+1)/(2*E33)), 2*E36*(2*E35-1)) -> 0 | F32: =IFERROR(10*F33*F35/(F34+1)+10*(F35-1)*((F34+1)/(2*F33)), 2*F36*(2*F35-1)) -> 0 | G32: =IFERROR(10*G33*G35/(G34+1)+10*(G35-1)*((G34+1)/(2*G33)), 2*G36*(2*G35-1)) -> 0 | H32: =IFERROR(10*H33*H35/(H34+1)+10*(H35-1)*((H34+1)/(2*H33)), 2*H36*(2*H35-1)) -> 0 | I32: =IFERROR(10*I33*I35/(I34+1)+10*(I35-1)*((I34+1)/(2*I33)), 2*I36*(2*I35-1)) -> 0 | ... Y32: =IFERROR(10*Y33*Y35/(Y34+1)+10*(Y35-1)*((Y34+1)/(2*Y33)), 2*Y36*(2*Y35-1)) -> 0
A33: # of Enemies:
A34: # of Allies:
A35: Win?
A36: Condots?

Sheet Session 5
B1: ='Total Score'!B1 -> Llama | C1: ='Total Score'!C1 -> Nic | D1: ='Total Score'!D1 -> Taank | E1: ='Total Score'!E1 -> Elephant | F1: ='Total Score'!F1 -> Jorg | G1: ='Total Score'!G1 -> Deadlock | H1: ='Total Score'!H1 -> Veil | I1: ='Total Score'!I1 -> Arch | ... Y1: ='Total Score'!Y1
A2: War 1: | B2: =IFERROR(10*B3*B5/(B4+1)+10*(B5-1)*((B4+1)/(2*B3)), 2*B6*(2*B5-1)) -> 0 | C2: =IFERROR(10*C3*C5/(C4+1)+10*(C5-1)*((C4+1)/(2*C3)), 2*C6*(2*C5-1)) -> 0 | D2: =IFERROR(10*D3*D5/(D4+1)+10*(D5-1)*((D4+1)/(2*D3)), 2*D6*(2*D5-1)) -> 0 | E2: =IFERROR(10*E3*E5/(E4+1)+10*(E5-1)*((E4+1)/(2*E3)), 2*E6*(2*E5-1)) -> 0 | F2: =IFERROR(10*F3*F5/(F4+1)+10*(F5-1)*((F4+1)/(2*F3)), 2*F6*(2*F5-1)) -> 0 | G2: =IFERROR(10*G3*G5/(G4+1)+10*(G5-1)*((G4+1)/(2*G3)), 2*G6*(2*G5-1)) -> 0 | H2: =IFERROR(10*H3*H5/(H4+1)+10*(H5-1)*((H4+1)/(2*H3)), 2*H6*(2*H5-1)) -> 0 | I2: =IFERROR(10*I3*I5/(I4+1)+10*(I5-1)*((I4+1)/(2*I3)), 2*I6*(2*I5-1)) -> 0 | ... Y2: =IFERROR(10*Y3*Y5/(Y4+1)+10*(Y5-1)*((Y4+1)/(2*Y3)), 2*Y6*(2*Y5-1)) -> 0
A3: # of Enemies:
A4: # of Allies:
A5: Win?
A6: Condots?
A7: War 2: | B7: =IFERROR(10*B8*B10/(B9+1)+10*(B10-1)*((B9+1)/(2*B8)), 2*B11*(2*B10-1)) -> 0 | C7: =IFERROR(10*C8*C10/(C9+1)+10*(C10-1)*((C9+1)/(2*C8)), 2*C11*(2*C10-1)) -> 0 | D7: =IFERROR(10*D8*D10/(D9+1)+10*(D10-1)*((D9+1)/(2*D8)), 2*D11*(2*D10-1)) -> 0 | E7: =IFERROR(10*E8*E10/(E9+1)+10*(E10-1)*((E9+1)/(2*E8)), 2*E11*(2*E10-1)) -> 0 | F7: =IFERROR(10*F8*F10/(F9+1)+10*(F10-1)*((F9+1)/(2*F8)), 2*F11*(2*F10-1)) -> 0 | G7: =IFERROR(10*G8*G10/(G9+1)+10*(G10-1)*((G9+1)/(2*G8)), 2*G11*(2*G10-1)) -> 0 | H7: =IFERROR(10*H8*H10/(H9+1)+10*(H10-1)*((H9+1)/(2*H8)), 2*H11*(2*H10-1)) -> 0 | I7: =IFERROR(10*I8*I10/(I9+1)+10*(I10-1)*((I9+1)/(2*I8)), 2*I11*(2*I10-1)) -> 0 | ... Y7: =IFERROR(10*Y8*Y10/(Y9+1)+10*(Y10-1)*((Y9+1)/(2*Y8)), 2*Y11*(2*Y10-1)) -> 0
A8: # of Enemies:
A9: # of Allies:
A10: Win?
A11: Condots?
A12: War 3: | B12: =IFERROR(10*B13*B15/(B14+1)+10*(B15-1)*((B14+1)/(2*B13)), 2*B16*(2*B15-1)) -> 0 | C12: =IFERROR(10*C13*C15/(C14+1)+10*(C15-1)*((C14+1)/(2*C13)), 2*C16*(2*C15-1)) -> 0 | D12: =IFERROR(10*D13*D15/(D14+1)+10*(D15-1)*((D14+1)/(2*D13)), 2*D16*(2*D15-1)) -> 0 | E12: =IFERROR(10*E13*E15/(E14+1)+10*(E15-1)*((E14+1)/(2*E13)), 2*E16*(2*E15-1)) -> 0 | F12: =IFERROR(10*F13*F15/(F14+1)+10*(F15-1)*((F14+1)/(2*F13)), 2*F16*(2*F15-1)) -> 0 | G12: =IFERROR(10*G13*G15/(G14+1)+10*(G15-1)*((G14+1)/(2*G13)), 2*G16*(2*G15-1)) -> 0 | H12: =IFERROR(10*H13*H15/(H14+1)+10*(H15-1)*((H14+1)/(2*H13)), 2*H16*(2*H15-1)) -> 0 | I12: =IFERROR(10*I13*I15/(I14+1)+10*(I15-1)*((I14+1)/(2*I13)), 2*I16*(2*I15-1)) -> 0 | ... Y12: =IFERROR(10*Y13*Y15/(Y14+1)+10*(Y15-1)*((Y14+1)/(2*Y13)), 2*Y16*(2*Y15-1)) -> 0
A13: # of Enemies:
A14: # of Allies:
A15: Win?
A16: Condots?
A17: War 4: | B17: =IFERROR(10*B18*B20/(B19+1)+10*(B20-1)*((B19+1)/(2*B18)), 2*B21*(2*B20-1)) -> 0 | C17: =IFERROR(10*C18*C20/(C19+1)+10*(C20-1)*((C19+1)/(2*C18)), 2*C21*(2*C20-1)) -> 0 | D17: =IFERROR(10*D18*D20/(D19+1)+10*(D20-1)*((D19+1)/(2*D18)), 2*D21*(2*D20-1)) -> 0 | E17: =IFERROR(10*E18*E20/(E19+1)+10*(E20-1)*((E19+1)/(2*E18)), 2*E21*(2*E20-1)) -> 0 | F17: =IFERROR(10*F18*F20/(F19+1)+10*(F20-1)*((F19+1)/(2*F18)), 2*F21*(2*F20-1)) -> 0 | G17: =IFERROR(10*G18*G20/(G19+1)+10*(G20-1)*((G19+1)/(2*G18)), 2*G21*(2*G20-1)) -> 0 | H17: =IFERROR(10*H18*H20/(H19+1)+10*(H20-1)*((H19+1)/(2*H18)), 2*H21*(2*H20-1)) -> 0 | I17: =IFERROR(10*I18*I20/(I19+1)+10*(I20-1)*((I19+1)/(2*I18)), 2*I21*(2*I20-1)) -> 0 | ... Y17: =IFERROR(10*Y18*Y20/(Y19+1)+10*(Y20-1)*((Y19+1)/(2*Y18)), 2*Y21*(2*Y20-1)) -> 0
A18: # of Enemies:
A19: # of Allies:
A20: Win?
A21: Condots?
A22: War 5: | B22: =IFERROR(10*B23*B25/(B24+1)+10*(B25-1)*((B24+1)/(2*B23)), 2*B26*(2*B25-1)) -> 0 | C22: =IFERROR(10*C23*C25/(C24+1)+10*(C25-1)*((C24+1)/(2*C23)), 2*C26*(2*C25-1)) -> 0 | D22: =IFERROR(10*D23*D25/(D24+1)+10*(D25-1)*((D24+1)/(2*D23)), 2*D26*(2*D25-1)) -> 0 | E22: =IFERROR(10*E23*E25/(E24+1)+10*(E25-1)*((E24+1)/(2*E23)), 2*E26*(2*E25-1)) -> 0 | F22: =IFERROR(10*F23*F25/(F24+1)+10*(F25-1)*((F24+1)/(2*F23)), 2*F26*(2*F25-1)) -> 0 | G22: =IFERROR(10*G23*G25/(G24+1)+10*(G25-1)*((G24+1)/(2*G23)), 2*G26*(2*G25-1)) -> 0 | H22: =IFERROR(10*H23*H25/(H24+1)+10*(H25-1)*((H24+1)/(2*H23)), 2*H26*(2*H25-1)) -> 0 | I22: =IFERROR(10*I23*I25/(I24+1)+10*(I25-1)*((I24+1)/(2*I23)), 2*I26*(2*I25-1)) -> 0 | ... Y22: =IFERROR(10*Y23*Y25/(Y24+1)+10*(Y25-1)*((Y24+1)/(2*Y23)), 2*Y26*(2*Y25-1)) -> 0
A23: # of Enemies:
A24: # of Allies:
A25: Win?
A26: Condots?
A27: War 6: | B27: =IFERROR(10*B28*B30/(B29+1)+10*(B30-1)*((B29+1)/(2*B28)), 2*B31*(2*B30-1)) -> 0 | C27: =IFERROR(10*C28*C30/(C29+1)+10*(C30-1)*((C29+1)/(2*C28)), 2*C31*(2*C30-1)) -> 0 | D27: =IFERROR(10*D28*D30/(D29+1)+10*(D30-1)*((D29+1)/(2*D28)), 2*D31*(2*D30-1)) -> 0 | E27: =IFERROR(10*E28*E30/(E29+1)+10*(E30-1)*((E29+1)/(2*E28)), 2*E31*(2*E30-1)) -> 0 | F27: =IFERROR(10*F28*F30/(F29+1)+10*(F30-1)*((F29+1)/(2*F28)), 2*F31*(2*F30-1)) -> 0 | G27: =IFERROR(10*G28*G30/(G29+1)+10*(G30-1)*((G29+1)/(2*G28)), 2*G31*(2*G30-1)) -> 0 | H27: =IFERROR(10*H28*H30/(H29+1)+10*(H30-1)*((H29+1)/(2*H28)), 2*H31*(2*H30-1)) -> 0 | I27: =IFERROR(10*I28*I30/(I29+1)+10*(I30-1)*((I29+1)/(2*I28)), 2*I31*(2*I30-1)) -> 0 | ... Y27: =IFERROR(10*Y28*Y30/(Y29+1)+10*(Y30-1)*((Y29+1)/(2*Y28)), 2*Y31*(2*Y30-1)) -> 0
A28: # of Enemies:
A29: # of Allies:
A30: Win?
A31: Condots?
A32: War 7: | B32: =IFERROR(10*B33*B35/(B34+1)+10*(B35-1)*((B34+1)/(2*B33)), 2*B36*(2*B35-1)) -> 0 | C32: =IFERROR(10*C33*C35/(C34+1)+10*(C35-1)*((C34+1)/(2*C33)), 2*C36*(2*C35-1)) -> 0 | D32: =IFERROR(10*D33*D35/(D34+1)+10*(D35-1)*((D34+1)/(2*D33)), 2*D36*(2*D35-1)) -> 0 | E32: =IFERROR(10*E33*E35/(E34+1)+10*(E35-1)*((E34+1)/(2*E33)), 2*E36*(2*E35-1)) -> 0 | F32: =IFERROR(10*F33*F35/(F34+1)+10*(F35-1)*((F34+1)/(2*F33)), 2*F36*(2*F35-1)) -> 0 | G32: =IFERROR(10*G33*G35/(G34+1)+10*(G35-1)*((G34+1)/(2*G33)), 2*G36*(2*G35-1)) -> 0 | H32: =IFERROR(10*H33*H35/(H34+1)+10*(H35-1)*((H34+1)/(2*H33)), 2*H36*(2*H35-1)) -> 0 | I32: =IFERROR(10*I33*I35/(I34+1)+10*(I35-1)*((I34+1)/(2*I33)), 2*I36*(2*I35-1)) -> 0 | ... Y32: =IFERROR(10*Y33*Y35/(Y34+1)+10*(Y35-1)*((Y34+1)/(2*Y33)), 2*Y36*(2*Y35-1)) -> 0
A33: # of Enemies:
A34: # of Allies:
A35: Win?
A36: Condots?

Sheet Session 6
B1: ='Total Score'!B1 -> Llama | C1: ='Total Score'!C1 -> Nic | D1: ='Total Score'!D1 -> Taank | E1: ='Total Score'!E1 -> Elephant | F1: ='Total Score'!F1 -> Jorg | G1: ='Total Score'!G1 -> Deadlock | H1: ='Total Score'!H1 -> Veil | I1: ='Total Score'!I1 -> Arch | ... Y1: ='Total Score'!Y1
A2: War 1: | B2: =IFERROR(10*B3*B5/(B4+1)+10*(B5-1)*((B4+1)/(2*B3)), 2*B6*(2*B5-1)) -> 0 | C2: =IFERROR(10*C3*C5/(C4+1)+10*(C5-1)*((C4+1)/(2*C3)), 2*C6*(2*C5-1)) -> 0 | D2: =IFERROR(10*D3*D5/(D4+1)+10*(D5-1)*((D4+1)/(2*D3)), 2*D6*(2*D5-1)) -> 0 | E2: =IFERROR(10*E3*E5/(E4+1)+10*(E5-1)*((E4+1)/(2*E3)), 2*E6*(2*E5-1)) -> 0 | F2: =IFERROR(10*F3*F5/(F4+1)+10*(F5-1)*((F4+1)/(2*F3)), 2*F6*(2*F5-1)) -> 0 | G2: =IFERROR(10*G3*G5/(G4+1)+10*(G5-1)*((G4+1)/(2*G3)), 2*G6*(2*G5-1)) -> 0 | H2: =IFERROR(10*H3*H5/(H4+1)+10*(H5-1)*((H4+1)/(2*H3)), 2*H6*(2*H5-1)) -> 0 | I2: =IFERROR(10*I3*I5/(I4+1)+10*(I5-1)*((I4+1)/(2*I3)), 2*I6*(2*I5-1)) -> 0 | ... Y2: =IFERROR(10*Y3*Y5/(Y4+1)+10*(Y5-1)*((Y4+1)/(2*Y3)), 2*Y6*(2*Y5-1)) -> 0
A3: # of Enemies:
A4: # of Allies:
A5: Win?
A6: Condots?
A7: War 2: | B7: =IFERROR(10*B8*B10/(B9+1)+10*(B10-1)*((B9+1)/(2*B8)), 2*B11*(2*B10-1)) -> 0 | C7: =IFERROR(10*C8*C10/(C9+1)+10*(C10-1)*((C9+1)/(2*C8)), 2*C11*(2*C10-1)) -> 0 | D7: =IFERROR(10*D8*D10/(D9+1)+10*(D10-1)*((D9+1)/(2*D8)), 2*D11*(2*D10-1)) -> 0 | E7: =IFERROR(10*E8*E10/(E9+1)+10*(E10-1)*((E9+1)/(2*E8)), 2*E11*(2*E10-1)) -> 0 | F7: =IFERROR(10*F8*F10/(F9+1)+10*(F10-1)*((F9+1)/(2*F8)), 2*F11*(2*F10-1)) -> 0 | G7: =IFERROR(10*G8*G10/(G9+1)+10*(G10-1)*((G9+1)/(2*G8)), 2*G11*(2*G10-1)) -> 0 | H7: =IFERROR(10*H8*H10/(H9+1)+10*(H10-1)*((H9+1)/(2*H8)), 2*H11*(2*H10-1)) -> 0 | I7: =IFERROR(10*I8*I10/(I9+1)+10*(I10-1)*((I9+1)/(2*I8)), 2*I11*(2*I10-1)) -> 0 | ... Y7: =IFERROR(10*Y8*Y10/(Y9+1)+10*(Y10-1)*((Y9+1)/(2*Y8)), 2*Y11*(2*Y10-1)) -> 0
A8: # of Enemies:
A9: # of Allies:
A10: Win?
A11: Condots?
A12: War 3: | B12: =IFERROR(10*B13*B15/(B14+1)+10*(B15-1)*((B14+1)/(2*B13)), 2*B16*(2*B15-1)) -> 0 | C12: =IFERROR(10*C13*C15/(C14+1)+10*(C15-1)*((C14+1)/(2*C13)), 2*C16*(2*C15-1)) -> 0 | D12: =IFERROR(10*D13*D15/(D14+1)+10*(D15-1)*((D14+1)/(2*D13)), 2*D16*(2*D15-1)) -> 0 | E12: =IFERROR(10*E13*E15/(E14+1)+10*(E15-1)*((E14+1)/(2*E13)), 2*E16*(2*E15-1)) -> 0 | F12: =IFERROR(10*F13*F15/(F14+1)+10*(F15-1)*((F14+1)/(2*F13)), 2*F16*(2*F15-1)) -> 0 | G12: =IFERROR(10*G13*G15/(G14+1)+10*(G15-1)*((G14+1)/(2*G13)), 2*G16*(2*G15-1)) -> 0 | H12: =IFERROR(10*H13*H15/(H14+1)+10*(H15-1)*((H14+1)/(2*H13)), 2*H16*(2*H15-1)) -> 0 | I12: =IFERROR(10*I13*I15/(I14+1)+10*(I15-1)*((I14+1)/(2*I13)), 2*I16*(2*I15-1)) -> 0 | ... Y12: =IFERROR(10*Y13*Y15/(Y14+1)+10*(Y15-1)*((Y14+1)/(2*Y13)), 2*Y16*(2*Y15-1)) -> 0
A13: # of Enemies:
A14: # of Allies:
A15: Win?
A16: Condots?
A17: War 4: | B17: =IFERROR(10*B18*B20/(B19+1)+10*(B20-1)*((B19+1)/(2*B18)), 2*B21*(2*B20-1)) -> 0 | C17: =IFERROR(10*C18*C20/(C19+1)+10*(C20-1)*((C19+1)/(2*C18)), 2*C21*(2*C20-1)) -> 0 | D17: =IFERROR(10*D18*D20/(D19+1)+10*(D20-1)*((D19+1)/(2*D18)), 2*D21*(2*D20-1)) -> 0 | E17: =IFERROR(10*E18*E20/(E19+1)+10*(E20-1)*((E19+1)/(2*E18)), 2*E21*(2*E20-1)) -> 0 | F17: =IFERROR(10*F18*F20/(F19+1)+10*(F20-1)*((F19+1)/(2*F18)), 2*F21*(2*F20-1)) -> 0 | G17: =IFERROR(10*G18*G20/(G19+1)+10*(G20-1)*((G19+1)/(2*G18)), 2*G21*(2*G20-1)) -> 0 | H17: =IFERROR(10*H18*H20/(H19+1)+10*(H20-1)*((H19+1)/(2*H18)), 2*H21*(2*H20-1)) -> 0 | I17: =IFERROR(10*I18*I20/(I19+1)+10*(I20-1)*((I19+1)/(2*I18)), 2*I21*(2*I20-1)) -> 0 | ... Y17: =IFERROR(10*Y18*Y20/(Y19+1)+10*(Y20-1)*((Y19+1)/(2*Y18)), 2*Y21*(2*Y20-1)) -> 0
A18: # of Enemies:
A19: # of Allies:
A20: Win?
A21: Condots?
A22: War 5: | B22: =IFERROR(10*B23*B25/(B24+1)+10*(B25-1)*((B24+1)/(2*B23)), 2*B26*(2*B25-1)) -> 0 | C22: =IFERROR(10*C23*C25/(C24+1)+10*(C25-1)*((C24+1)/(2*C23)), 2*C26*(2*C25-1)) -> 0 | D22: =IFERROR(10*D23*D25/(D24+1)+10*(D25-1)*((D24+1)/(2*D23)), 2*D26*(2*D25-1)) -> 0 | E22: =IFERROR(10*E23*E25/(E24+1)+10*(E25-1)*((E24+1)/(2*E23)), 2*E26*(2*E25-1)) -> 0 | F22: =IFERROR(10*F23*F25/(F24+1)+10*(F25-1)*((F24+1)/(2*F23)), 2*F26*(2*F25-1)) -> 0 | G22: =IFERROR(10*G23*G25/(G24+1)+10*(G25-1)*((G24+1)/(2*G23)), 2*G26*(2*G25-1)) -> 0 | H22: =IFERROR(10*H23*H25/(H24+1)+10*(H25-1)*((H24+1)/(2*H23)), 2*H26*(2*H25-1)) -> 0 | I22: =IFERROR(10*I23*I25/(I24+1)+10*(I25-1)*((I24+1)/(2*I23)), 2*I26*(2*I25-1)) -> 0 | ... Y22: =IFERROR(10*Y23*Y25/(Y24+1)+10*(Y25-1)*((Y24+1)/(2*Y23)), 2*Y26*(2*Y25-1)) -> 0
A23: # of Enemies:
A24: # of Allies:
A25: Win?
A26: Condots?
A27: War 6: | B27: =IFERROR(10*B28*B30/(B29+1)+10*(B30-1)*((B29+1)/(2*B28)), 2*B31*(2*B30-1)) -> 0 | C27: =IFERROR(10*C28*C30/(C29+1)+10*(C30-1)*((C29+1)/(2*C28)), 2*C31*(2*C30-1)) -> 0 | D27: =IFERROR(10*D28*D30/(D29+1)+10*(D30-1)*((D29+1)/(2*D28)), 2*D31*(2*D30-1)) -> 0 | E27: =IFERROR(10*E28*E30/(E29+1)+10*(E30-1)*((E29+1)/(2*E28)), 2*E31*(2*E30-1)) -> 0 | F27: =IFERROR(10*F28*F30/(F29+1)+10*(F30-1)*((F29+1)/(2*F28)), 2*F31*(2*F30-1)) -> 0 | G27: =IFERROR(10*G28*G30/(G29+1)+10*(G30-1)*((G29+1)/(2*G28)), 2*G31*(2*G30-1)) -> 0 | H27: =IFERROR(10*H28*H30/(H29+1)+10*(H30-1)*((H29+1)/(2*H28)), 2*H31*(2*H30-1)) -> 0 | I27: =IFERROR(10*I28*I30/(I29+1)+10*(I30-1)*((I29+1)/(2*I28)), 2*I31*(2*I30-1)) -> 0 | ... Y27: =IFERROR(10*Y28*Y30/(Y29+1)+10*(Y30-1)*((Y29+1)/(2*Y28)), 2*Y31*(2*Y30-1)) -> 0
A28: # of Enemies:
A29: # of Allies:
A30: Win?
A31: Condots?
A32: War 7: | B32: =IFERROR(10*B33*B35/(B34+1)+10*(B35-1)*((B34+1)/(2*B33)), 2*B36*(2*B35-1)) -> 0 | C32: =IFERROR(10*C33*C35/(C34+1)+10*(C35-1)*((C34+1)/(2*C33)), 2*C36*(2*C35-1)) -> 0 | D32: =IFERROR(10*D33*D35/(D34+1)+10*(D35-1)*((D34+1)/(2*D33)), 2*D36*(2*D35-1)) -> 0 | E32: =IFERROR(10*E33*E35/(E34+1)+10*(E35-1)*((E34+1)/(2*E33)), 2*E36*(2*E35-1)) -> 0 | F32: =IFERROR(10*F33*F35/(F34+1)+10*(F35-1)*((F34+1)/(2*F33)), 2*F36*(2*F35-1)) -> 0 | G32: =IFERROR(10*G33*G35/(G34+1)+10*(G35-1)*((G34+1)/(2*G33)), 2*G36*(2*G35-1)) -> 0 | H32: =IFERROR(10*H33*H35/(H34+1)+10*(H35-1)*((H34+1)/(2*H33)), 2*H36*(2*H35-1)) -> 0 | I32: =IFERROR(10*I33*I35/(I34+1)+10*(I35-1)*((I34+1)/(2*I33)), 2*I36*(2*I35-1)) -> 0 | ... Y32: =IFERROR(10*Y33*Y35/(Y34+1)+10*(Y35-1)*((Y34+1)/(2*Y33)), 2*Y36*(2*Y35-1)) -> 0
A33: # of Enemies:
A34: # of Allies:
A35: Win?
A36: Condots?

Sheet Session 7
B1: ='Total Score'!B1 -> Llama | C1: ='Total Score'!C1 -> Nic | D1: ='Total Score'!D1 -> Taank | E1: ='Total Score'!E1 -> Elephant | F1: ='Total Score'!F1 -> Jorg | G1: ='Total Score'!G1 -> Deadlock | H1: ='Total Score'!H1 -> Veil | I1: ='Total Score'!I1 -> Arch | ... Y1: ='Total Score'!Y1
A2: War 1: | B2: =IFERROR(10*B3*B5/(B4+1)+10*(B5-1)*((B4+1)/(2*B3)), 2*B6*(2*B5-1)) -> 0 | C2: =IFERROR(10*C3*C5/(C4+1)+10*(C5-1)*((C4+1)/(2*C3)), 2*C6*(2*C5-1)) -> 0 | D2: =IFERROR(10*D3*D5/(D4+1)+10*(D5-1)*((D4+1)/(2*D3)), 2*D6*(2*D5-1)) -> 0 | E2: =IFERROR(10*E3*E5/(E4+1)+10*(E5-1)*((E4+1)/(2*E3)), 2*E6*(2*E5-1)) -> 0 | F2: =IFERROR(10*F3*F5/(F4+1)+10*(F5-1)*((F4+1)/(2*F3)), 2*F6*(2*F5-1)) -> 0 | G2: =IFERROR(10*G3*G5/(G4+1)+10*(G5-1)*((G4+1)/(2*G3)), 2*G6*(2*G5-1)) -> 0 | H2: =IFERROR(10*H3*H5/(H4+1)+10*(H5-1)*((H4+1)/(2*H3)), 2*H6*(2*H5-1)) -> 0 | I2: =IFERROR(10*I3*I5/(I4+1)+10*(I5-1)*((I4+1)/(2*I3)), 2*I6*(2*I5-1)) -> 0 | ... Y2: =IFERROR(10*Y3*Y5/(Y4+1)+10*(Y5-1)*((Y4+1)/(2*Y3)), 2*Y6*(2*Y5-1)) -> 0
A3: # of Enemies:
A4: # of Allies:
A5: Win?
A6: Condots?
A7: War 2: | B7: =IFERROR(10*B8*B10/(B9+1)+10*(B10-1)*((B9+1)/(2*B8)), 2*B11*(2*B10-1)) -> 0 | C7: =IFERROR(10*C8*C10/(C9+1)+10*(C10-1)*((C9+1)/(2*C8)), 2*C11*(2*C10-1)) -> 0 | D7: =IFERROR(10*D8*D10/(D9+1)+10*(D10-1)*((D9+1)/(2*D8)), 2*D11*(2*D10-1)) -> 0 | E7: =IFERROR(10*E8*E10/(E9+1)+10*(E10-1)*((E9+1)/(2*E8)), 2*E11*(2*E10-1)) -> 0 | F7: =IFERROR(10*F8*F10/(F9+1)+10*(F10-1)*((F9+1)/(2*F8)), 2*F11*(2*F10-1)) -> 0 | G7: =IFERROR(10*G8*G10/(G9+1)+10*(G10-1)*((G9+1)/(2*G8)), 2*G11*(2*G10-1)) -> 0 | H7: =IFERROR(10*H8*H10/(H9+1)+10*(H10-1)*((H9+1)/(2*H8)), 2*H11*(2*H10-1)) -> 0 | I7: =IFERROR(10*I8*I10/(I9+1)+10*(I10-1)*((I9+1)/(2*I8)), 2*I11*(2*I10-1)) -> 0 | ... Y7: =IFERROR(10*Y8*Y10/(Y9+1)+10*(Y10-1)*((Y9+1)/(2*Y8)), 2*Y11*(2*Y10-1)) -> 0
A8: # of Enemies:
A9: # of Allies:
A10: Win?
A11: Condots?
A12: War 3: | B12: =IFERROR(10*B13*B15/(B14+1)+10*(B15-1)*((B14+1)/(2*B13)), 2*B16*(2*B15-1)) -> 0 | C12: =IFERROR(10*C13*C15/(C14+1)+10*(C15-1)*((C14+1)/(2*C13)), 2*C16*(2*C15-1)) -> 0 | D12: =IFERROR(10*D13*D15/(D14+1)+10*(D15-1)*((D14+1)/(2*D13)), 2*D16*(2*D15-1)) -> 0 | E12: =IFERROR(10*E13*E15/(E14+1)+10*(E15-1)*((E14+1)/(2*E13)), 2*E16*(2*E15-1)) -> 0 | F12: =IFERROR(10*F13*F15/(F14+1)+10*(F15-1)*((F14+1)/(2*F13)), 2*F16*(2*F15-1)) -> 0 | G12: =IFERROR(10*G13*G15/(G14+1)+10*(G15-1)*((G14+1)/(2*G13)), 2*G16*(2*G15-1)) -> 0 | H12: =IFERROR(10*H13*H15/(H14+1)+10*(H15-1)*((H14+1)/(2*H13)), 2*H16*(2*H15-1)) -> 0 | I12: =IFERROR(10*I13*I15/(I14+1)+10*(I15-1)*((I14+1)/(2*I13)), 2*I16*(2*I15-1)) -> 0 | ... Y12: =IFERROR(10*Y13*Y15/(Y14+1)+10*(Y15-1)*((Y14+1)/(2*Y13)), 2*Y16*(2*Y15-1)) -> 0
A13: # of Enemies:
A14: # of Allies:
A15: Win?
A16: Condots?
A17: War 4: | B17: =IFERROR(10*B18*B20/(B19+1)+10*(B20-1)*((B19+1)/(2*B18)), 2*B21*(2*B20-1)) -> 0 | C17: =IFERROR(10*C18*C20/(C19+1)+10*(C20-1)*((C19+1)/(2*C18)), 2*C21*(2*C20-1)) -> 0 | D17: =IFERROR(10*D18*D20/(D19+1)+10*(D20-1)*((D19+1)/(2*D18)), 2*D21*(2*D20-1)) -> 0 | E17: =IFERROR(10*E18*E20/(E19+1)+10*(E20-1)*((E19+1)/(2*E18)), 2*E21*(2*E20-1)) -> 0 | F17: =IFERROR(10*F18*F20/(F19+1)+10*(F20-1)*((F19+1)/(2*F18)), 2*F21*(2*F20-1)) -> 0 | G17: =IFERROR(10*G18*G20/(G19+1)+10*(G20-1)*((G19+1)/(2*G18)), 2*G21*(2*G20-1)) -> 0 | H17: =IFERROR(10*H18*H20/(H19+1)+10*(H20-1)*((H19+1)/(2*H18)), 2*H21*(2*H20-1)) -> 0 | I17: =IFERROR(10*I18*I20/(I19+1)+10*(I20-1)*((I19+1)/(2*I18)), 2*I21*(2*I20-1)) -> 0 | ... Y17: =IFERROR(10*Y18*Y20/(Y19+1)+10*(Y20-1)*((Y19+1)/(2*Y18)), 2*Y21*(2*Y20-1)) -> 0
A18: # of Enemies:
A19: # of Allies:
A20: Win?
A21: Condots?
A22: War 5: | B22: =IFERROR(10*B23*B25/(B24+1)+10*(B25-1)*((B24+1)/(2*B23)), 2*B26*(2*B25-1)) -> 0 | C22: =IFERROR(10*C23*C25/(C24+1)+10*(C25-1)*((C24+1)/(2*C23)), 2*C26*(2*C25-1)) -> 0 | D22: =IFERROR(10*D23*D25/(D24+1)+10*(D25-1)*((D24+1)/(2*D23)), 2*D26*(2*D25-1)) -> 0 | E22: =IFERROR(10*E23*E25/(E24+1)+10*(E25-1)*((E24+1)/(2*E23)), 2*E26*(2*E25-1)) -> 0 | F22: =IFERROR(10*F23*F25/(F24+1)+10*(F25-1)*((F24+1)/(2*F23)), 2*F26*(2*F25-1)) -> 0 | G22: =IFERROR(10*G23*G25/(G24+1)+10*(G25-1)*((G24+1)/(2*G23)), 2*G26*(2*G25-1)) -> 0 | H22: =IFERROR(10*H23*H25/(H24+1)+10*(H25-1)*((H24+1)/(2*H23)), 2*H26*(2*H25-1)) -> 0 | I22: =IFERROR(10*I23*I25/(I24+1)+10*(I25-1)*((I24+1)/(2*I23)), 2*I26*(2*I25-1)) -> 0 | ... Y22: =IFERROR(10*Y23*Y25/(Y24+1)+10*(Y25-1)*((Y24+1)/(2*Y23)), 2*Y26*(2*Y25-1)) -> 0
A23: # of Enemies:
A24: # of Allies:
A25: Win?
A26: Condots?
A27: War 6: | B27: =IFERROR(10*B28*B30/(B29+1)+10*(B30-1)*((B29+1)/(2*B28)), 2*B31*(2*B30-1)) -> 0 | C27: =IFERROR(10*C28*C30/(C29+1)+10*(C30-1)*((C29+1)/(2*C28)), 2*C31*(2*C30-1)) -> 0 | D27: =IFERROR(10*D28*D30/(D29+1)+10*(D30-1)*((D29+1)/(2*D28)), 2*D31*(2*D30-1)) -> 0 | E27: =IFERROR(10*E28*E30/(E29+1)+10*(E30-1)*((E29+1)/(2*E28)), 2*E31*(2*E30-1)) -> 0 | F27: =IFERROR(10*F28*F30/(F29+1)+10*(F30-1)*((F29+1)/(2*F28)), 2*F31*(2*F30-1)) -> 0 | G27: =IFERROR(10*G28*G30/(G29+1)+10*(G30-1)*((G29+1)/(2*G28)), 2*G31*(2*G30-1)) -> 0 | H27: =IFERROR(10*H28*H30/(H29+1)+10*(H30-1)*((H29+1)/(2*H28)), 2*H31*(2*H30-1)) -> 0 | I27: =IFERROR(10*I28*I30/(I29+1)+10*(I30-1)*((I29+1)/(2*I28)), 2*I31*(2*I30-1)) -> 0 | ... Y27: =IFERROR(10*Y28*Y30/(Y29+1)+10*(Y30-1)*((Y29+1)/(2*Y28)), 2*Y31*(2*Y30-1)) -> 0
A28: # of Enemies:
A29: # of Allies:
A30: Win?
A31: Condots?
A32: War 7: | B32: =IFERROR(10*B33*B35/(B34+1)+10*(B35-1)*((B34+1)/(2*B33)), 2*B36*(2*B35-1)) -> 0 | C32: =IFERROR(10*C33*C35/(C34+1)+10*(C35-1)*((C34+1)/(2*C33)), 2*C36*(2*C35-1)) -> 0 | D32: =IFERROR(10*D33*D35/(D34+1)+10*(D35-1)*((D34+1)/(2*D33)), 2*D36*(2*D35-1)) -> 0 | E32: =IFERROR(10*E33*E35/(E34+1)+10*(E35-1)*((E34+1)/(2*E33)), 2*E36*(2*E35-1)) -> 0 | F32: =IFERROR(10*F33*F35/(F34+1)+10*(F35-1)*((F34+1)/(2*F33)), 2*F36*(2*F35-1)) -> 0 | G32: =IFERROR(10*G33*G35/(G34+1)+10*(G35-1)*((G34+1)/(2*G33)), 2*G36*(2*G35-1)) -> 0 | H32: =IFERROR(10*H33*H35/(H34+1)+10*(H35-1)*((H34+1)/(2*H33)), 2*H36*(2*H35-1)) -> 0 | I32: =IFERROR(10*I33*I35/(I34+1)+10*(I35-1)*((I34+1)/(2*I33)), 2*I36*(2*I35-1)) -> 0 | ... Y32: =IFERROR(10*Y33*Y35/(Y34+1)+10*(Y35-1)*((Y34+1)/(2*Y33)), 2*Y36*(2*Y35-1)) -> 0
A33: # of Enemies:
A34: # of Allies:
A35: Win?
A36: Condots?

Sheet Session 8
B1: ='Total Score'!B1 -> Llama | C1: ='Total Score'!C1 -> Nic | D1: ='Total Score'!D1 -> Taank | E1: ='Total Score'!E1 -> Elephant | F1: ='Total Score'!F1 -> Jorg | G1: ='Total Score'!G1 -> Deadlock | H1: ='Total Score'!H1 -> Veil | I1: ='Total Score'!I1 -> Arch | ... Y1: ='Total Score'!Y1
A2: War 1: | B2: =IFERROR(10*B3*B5/(B4+1)+10*(B5-1)*((B4+1)/(2*B3)), 2*B6*(2*B5-1)) -> 0 | C2: =IFERROR(10*C3*C5/(C4+1)+10*(C5-1)*((C4+1)/(2*C3)), 2*C6*(2*C5-1)) -> 0 | D2: =IFERROR(10*D3*D5/(D4+1)+10*(D5-1)*((D4+1)/(2*D3)), 2*D6*(2*D5-1)) -> 0 | E2: =IFERROR(10*E3*E5/(E4+1)+10*(E5-1)*((E4+1)/(2*E3)), 2*E6*(2*E5-1)) -> 0 | F2: =IFERROR(10*F3*F5/(F4+1)+10*(F5-1)*((F4+1)/(2*F3)), 2*F6*(2*F5-1)) -> 0 | G2: =IFERROR(10*G3*G5/(G4+1)+10*(G5-1)*((G4+1)/(2*G3)), 2*G6*(2*G5-1)) -> 0 | H2: =IFERROR(10*H3*H5/(H4+1)+10*(H5-1)*((H4+1)/(2*H3)), 2*H6*(2*H5-1)) -> 0 | I2: =IFERROR(10*I3*I5/(I4+1)+10*(I5-1)*((I4+1)/(2*I3)), 2*I6*(2*I5-1)) -> 0 | ... Y2: =IFERROR(10*Y3*Y5/(Y4+1)+10*(Y5-1)*((Y4+1)/(2*Y3)), 2*Y6*(2*Y5-1)) -> 0
A3: # of Enemies:
A4: # of Allies:
A5: Win?
A6: Condots?
A7: War 2: | B7: =IFERROR(10*B8*B10/(B9+1)+10*(B10-1)*((B9+1)/(2*B8)), 2*B11*(2*B10-1)) -> 0 | C7: =IFERROR(10*C8*C10/(C9+1)+10*(C10-1)*((C9+1)/(2*C8)), 2*C11*(2*C10-1)) -> 0 | D7: =IFERROR(10*D8*D10/(D9+1)+10*(D10-1)*((D9+1)/(2*D8)), 2*D11*(2*D10-1)) -> 0 | E7: =IFERROR(10*E8*E10/(E9+1)+10*(E10-1)*((E9+1)/(2*E8)), 2*E11*(2*E10-1)) -> 0 | F7: =IFERROR(10*F8*F10/(F9+1)+10*(F10-1)*((F9+1)/(2*F8)), 2*F11*(2*F10-1)) -> 0 | G7: =IFERROR(10*G8*G10/(G9+1)+10*(G10-1)*((G9+1)/(2*G8)), 2*G11*(2*G10-1)) -> 0 | H7: =IFERROR(10*H8*H10/(H9+1)+10*(H10-1)*((H9+1)/(2*H8)), 2*H11*(2*H10-1)) -> 0 | I7: =IFERROR(10*I8*I10/(I9+1)+10*(I10-1)*((I9+1)/(2*I8)), 2*I11*(2*I10-1)) -> 0 | ... Y7: =IFERROR(10*Y8*Y10/(Y9+1)+10*(Y10-1)*((Y9+1)/(2*Y8)), 2*Y11*(2*Y10-1)) -> 0
A8: # of Enemies:
A9: # of Allies:
A10: Win?
A11: Condots?
A12: War 3: | B12: =IFERROR(10*B13*B15/(B14+1)+10*(B15-1)*((B14+1)/(2*B13)), 2*B16*(2*B15-1)) -> 0 | C12: =IFERROR(10*C13*C15/(C14+1)+10*(C15-1)*((C14+1)/(2*C13)), 2*C16*(2*C15-1)) -> 0 | D12: =IFERROR(10*D13*D15/(D14+1)+10*(D15-1)*((D14+1)/(2*D13)), 2*D16*(2*D15-1)) -> 0 | E12: =IFERROR(10*E13*E15/(E14+1)+10*(E15-1)*((E14+1)/(2*E13)), 2*E16*(2*E15-1)) -> 0 | F12: =IFERROR(10*F13*F15/(F14+1)+10*(F15-1)*((F14+1)/(2*F13)), 2*F16*(2*F15-1)) -> 0 | G12: =IFERROR(10*G13*G15/(G14+1)+10*(G15-1)*((G14+1)/(2*G13)), 2*G16*(2*G15-1)) -> 0 | H12: =IFERROR(10*H13*H15/(H14+1)+10*(H15-1)*((H14+1)/(2*H13)), 2*H16*(2*H15-1)) -> 0 | I12: =IFERROR(10*I13*I15/(I14+1)+10*(I15-1)*((I14+1)/(2*I13)), 2*I16*(2*I15-1)) -> 0 | ... Y12: =IFERROR(10*Y13*Y15/(Y14+1)+10*(Y15-1)*((Y14+1)/(2*Y13)), 2*Y16*(2*Y15-1)) -> 0
A13: # of Enemies:
A14: # of Allies:
A15: Win?
A16: Condots?
